Workbook
Name Camkapama: #REF!
Name Camkapama: #REF!
Name Camkapama: #REF!
Name Camkapama: #REF!
Name Camkapama: #REF!
Name Camkapama: #REF!
Name Camkapama: #REF!
Name Camkapama: #REF!
Name Camkapama: #REF!
Name Camkapama: #REF!
Name Camkapama: #REF!
Name Camkapama: #REF!
Name Camkapama: #REF!
Name Camkapama: #REF!
Name Camkapama: #REF!
Name Camkapama: #REF!
Name Camkapama: #REF!
Name Camkapama: #REF!
Name Camkapama: #REF!
Name Camkapama: #REF!
Name Camkapama: #REF!
Name Camkapama: #REF!
Name Camkapama: #REF!
Name Camkapama: #REF!
Name Camkapama: #REF!
Name Camkapama: #REF!
Name Camkapama: #REF!
Name Camkapama: #REF!
Name Camkapama: #REF!
Name Camkapama: #REF!
Name Camkapama: #REF!
Name Excel_BuiltIn_Print_Area_1_1: #REF!
Name Excel_BuiltIn_Print_Area_1_1: #REF!
Name Excel_BuiltIn_Print_Area_1_1: #REF!
Name Excel_BuiltIn_Print_Area_1_1: #REF!
Name Excel_BuiltIn_Print_Area_1_1: #REF!
Name Excel_BuiltIn_Print_Area_1_1: #REF!
Name Excel_BuiltIn_Print_Area_1_1: #REF!
Name Excel_BuiltIn_Print_Area_1_1: #REF!
Name Excel_BuiltIn_Print_Area_1_1: #REF!
Name Excel_BuiltIn_Print_Area_1_1: #REF!
Name Excel_BuiltIn_Print_Area_1_1: #REF!
Name Excel_BuiltIn_Print_Area_1_1: #REF!
Name Excel_BuiltIn_Print_Area_1_1: #REF!
Name Excel_BuiltIn_Print_Area_1_1: #REF!
Name Excel_BuiltIn_Print_Area_1_1: #REF!
Name Excel_BuiltIn_Print_Area_1_1: #REF!
Name Excel_BuiltIn_Print_Area_1_1: #REF!
Name Excel_BuiltIn_Print_Area_1_1: #REF!
Name Excel_BuiltIn_Print_Area_1_1: #REF!
Name Excel_BuiltIn_Print_Area_1_1: #REF!
Name Excel_BuiltIn_Print_Area_1_1: #REF!
Name Excel_BuiltIn_Print_Area_1_1: #REF!
Name Excel_BuiltIn_Print_Area_1_1: #REF!
Name Excel_BuiltIn_Print_Area_1_1: #REF!
Name Excel_BuiltIn_Print_Area_1_1: #REF!
Name Excel_BuiltIn_Print_Area_1_1: #REF!
Name Excel_BuiltIn_Print_Area_1_1: #REF!
Name Excel_BuiltIn_Print_Area_1_1: #REF!
Name Excel_BuiltIn_Print_Area_1_1: #REF!

Sheet R.H.
A1: Ürün Kodu | B1: Ürün Tanımı | C1: Planlanan Hurda Oranı | E1: Açıklama
A2: 150060073 | B2: =VLOOKUP(A2,SÜRELER!A:B,2,0) -> #N/A | C2: 10 | F2: 1500600 | G2: =CONCATENATE($F$2,A2,) -> 1500600150060073
A3: 150060074 | B3: =VLOOKUP(A3,SÜRELER!A:B,2,0) -> #N/A | C3: 10 | G3: =CONCATENATE($F$2,A3,) -> 1500600150060074
A4: 150060075 | B4: =VLOOKUP(A4,SÜRELER!A:B,2,0) -> #N/A | C4: 10 | G4: =CONCATENATE($F$2,A4,) -> 1500600150060075
A5: 150060076 | B5: =VLOOKUP(A5,SÜRELER!A:B,2,0) -> #N/A | C5: 10 | G5: =CONCATENATE($F$2,A5,) -> 1500600150060076
A6: 150060077 | B6: =VLOOKUP(A6,SÜRELER!A:B,2,0) -> #N/A | C6: 10 | G6: =CONCATENATE($F$2,A6,) -> 1500600150060077
A7: 150060078 | B7: =VLOOKUP(A7,SÜRELER!A:B,2,0) -> #N/A | C7: 10 | G7: =CONCATENATE($F$2,A7,) -> 1500600150060078
A8: 150060079 | B8: =VLOOKUP(A8,SÜRELER!A:B,2,0) -> #N/A | C8: 10 | G8: =CONCATENATE($F$2,A8,) -> 1500600150060079
A9: 150060080 | B9: =VLOOKUP(A9,SÜRELER!A:B,2,0) -> #N/A | C9: 10 | G9: =CONCATENATE($F$2,A9,) -> 1500600150060080
A10: 150060081 | B10: =VLOOKUP(A10,SÜRELER!A:B,2,0) -> #N/A | C10: 10 | G10: =CONCATENATE($F$2,A10,) -> 1500600150060081
A11: 150060082 | B11: =VLOOKUP(A11,SÜRELER!A:B,2,0) -> #N/A | C11: 10 | G11: =CONCATENATE($F$2,A11,) -> 1500600150060082
A12: 150060083 | B12: =VLOOKUP(A12,SÜRELER!A:B,2,0) -> #N/A | C12: 10 | G12: =CONCATENATE($F$2,A12,) -> 1500600150060083
A13: 150060084 | B13: =VLOOKUP(A13,SÜRELER!A:B,2,0) -> #N/A | C13: 10 | G13: =CONCATENATE($F$2,A13,) -> 1500600150060084
A14: 150060085 | B14: =VLOOKUP(A14,SÜRELER!A:B,2,0) -> #N/A | C14: 10 | G14: =CONCATENATE($F$2,A14,) -> 1500600150060085
... A22: 150060093 | B22: =VLOOKUP(A22,SÜRELER!A:B,2,0) -> #N/A | C22: 10 | G22: =CONCATENATE($F$2,A22,) -> 1500600150060093
A23: 150060140 | B23: =VLOOKUP(A23,SÜRELER!A:B,2,0) -> #N/A | C23: 10 | F23: 150060 | G23: =CONCATENATE($F$23,A23,) -> 150060150060140
A24: 150060150 | B24: =VLOOKUP(A24,SÜRELER!A:B,2,0) -> #N/A | C24: 10 | G24: =CONCATENATE($F$23,A24,) -> 150060150060150
A25: 150060162 | B25: =VLOOKUP(A25,SÜRELER!A:B,2,0) -> #N/A | C25: 10 | G25: =CONCATENATE($F$23,A25,) -> 150060150060162
A26: 150060163 | B26: =VLOOKUP(A26,SÜRELER!A:B,2,0) -> #N/A | C26: 8 | G26: =CONCATENATE($F$23,A26,) -> 150060150060163
A27: 150060166 | B27: =VLOOKUP(A27,SÜRELER!A:B,2,0) -> #N/A | C27: 8 | G27: =CONCATENATE($F$23,A27,) -> 150060150060166
A28: 150060170 | B28: =VLOOKUP(A28,SÜRELER!A:B,2,0) -> #N/A | C28: 8 | G28: =CONCATENATE($F$23,A28,) -> 150060150060170
A29: 150060175 | B29: =VLOOKUP(A29,SÜRELER!A:B,2,0) -> #N/A | C29: 10 | G29: =CONCATENATE($F$23,A29,) -> 150060150060175
A30: 150160175 | B30: =VLOOKUP(A30,SÜRELER!A:B,2,0) -> #N/A | C30: 0 | G30: =CONCATENATE($F$23,A30,) -> 150060150160175
A31: 150060176 | B31: =VLOOKUP(A31,SÜRELER!A:B,2,0) -> #N/A | C31: 10 | G31: =CONCATENATE($F$23,A31,) -> 150060150060176
A32: 150060200 | B32: =VLOOKUP(A32,SÜRELER!A:B,2,0) -> #N/A | C32: 10 | G32: =CONCATENATE($F$23,A32,) -> 150060150060200
A33: 150060201 | B33: =VLOOKUP(A33,SÜRELER!A:B,2,0) -> #N/A | C33: 10 | G33: =CONCATENATE($F$23,A33,) -> 150060150060201
A34: 150060202 | B34: =VLOOKUP(A34,SÜRELER!A:B,2,0) -> #N/A | C34: 10 | G34: =CONCATENATE($F$23,A34,) -> 150060150060202
A35: 150060203 | B35: =VLOOKUP(A35,SÜRELER!A:B,2,0) -> #N/A | C35: 10 | G35: =CONCATENATE($F$23,A35,) -> 150060150060203
A36: 150060204 | B36: =VLOOKUP(A36,SÜRELER!A:B,2,0) -> #N/A | C36: 10 | G36: =CONCATENATE($F$23,A36,) -> 150060150060204
A37: 150060205 | B37: =VLOOKUP(A37,SÜRELER!A:B,2,0) -> #N/A | C37: 10 | G37: =CONCATENATE($F$23,A37,) -> 150060150060205
A38: 150060206 | B38: =VLOOKUP(A38,SÜRELER!A:B,2,0) -> #N/A | C38: 10 | G38: =CONCATENATE($F$23,A38,) -> 150060150060206
A39: 150060246 | B39: =VLOOKUP(A39,SÜRELER!A:B,2,0) -> #N/A | C39: 10 | G39: =CONCATENATE($F$23,A39,) -> 150060150060246
A40: 150060247 | B40: =VLOOKUP(A40,SÜRELER!A:B,2,0) -> #N/A | C40: 10 | G40: =CONCATENATE($F$23,A40,) -> 150060150060247
A41: 150060248 | B41: =VLOOKUP(A41,SÜRELER!A:B,2,0) -> #N/A | C41: 10 | G41: =CONCATENATE($F$23,A41,) -> 150060150060248
A42: 150060249 | B42: =VLOOKUP(A42,SÜRELER!A:B,2,0) -> #N/A | C42: 10 | G42: =CONCATENATE($F$23,A42,) -> 150060150060249
A43: 150060250 | B43: =VLOOKUP(A43,SÜRELER!A:B,2,0) -> #N/A | C43: 10 | E43: TEZGAH KAYNAKLI HATA | G43: =CONCATENATE($F$23,A43,) -> 150060150060250
A44: 150060251 | B44: =VLOOKUP(A44,SÜRELER!A:B,2,0) -> #N/A | C44: 10 | G44: =CONCATENATE($F$23,A44,) -> 150060150060251
A45: 150060252 | B45: =VLOOKUP(A45,SÜRELER!A:B,2,0) -> #N/A | C45: 10 | G45: =CONCATENATE($F$23,A45,) -> 150060150060252
A46: 150060253 | B46: =VLOOKUP(A46,SÜRELER!A:B,2,0) -> #N/A | C46: 10 | G46: =CONCATENATE($F$23,A46,) -> 150060150060253
A47: 150060254 | B47: =VLOOKUP(A47,SÜRELER!A:B,2,0) -> #N/A | C47: 10 | G47: =CONCATENATE($F$23,A47,) -> 150060150060254
...

Sheet SÜRELER
A1: Ürün Kodu | B1: Ürün Tanımı | C1: Birim İşçilik Süresi dk. | D1: Birim İşçilik Süresi sn. | E1: Saatlik Kapasite | F1: ürün süre
A2: 1500060050 | B2: Lens,Turuncu,Ön sinyal | C2: 1.19 | D2: 71.4 | E2: 50.420168 | F2: 1.19 | G2: 15000600 | H2: =CONCATENATE($G$2,A2) -> 150006001500060050
A3: 1500060051 | B3: Lens,Kirmizi,Arka sinyal | C3: 1.19 | D3: 71.4 | E3: 50.420168 | F3: 1.19 | H3: =CONCATENATE($G$2,A3) -> 150006001500060051
A4: 1500060055 | B4: Housing,Naturel,Büyük | C4: 0.59 | D4: 35.4 | E4: 101.69492 | F4: 0.59 | H4: =CONCATENATE($G$2,A4) -> 150006001500060055
A5: 1500060056 | B5: Housing,Naturel,Küçük | C5: 0.59 | D5: 35.4 | E5: 101.69492 | F5: 0.59 | H5: =CONCATENATE($G$2,A5) -> 150006001500060056
A6: 1500060060 | B6: Insert,Siyah,Küçük | C6: 0.72 | D6: 43.2 | E6: 83.333333 | F6: 0.72 | H6: =CONCATENATE($G$2,A6) -> 150006001500060060
A7: 1500060060 | B7: Reflektör,120x140,Terminalli,2'li | C7: 0.32 | D7: 19.2 | E7: 187.5 | F7: 0.32 | H7: =CONCATENATE($G$2,A7) -> 150006001500060060
A8: 1500060061 | B8: Insert,Siyah,Büyük | C8: 0.48 | D8: 28.8 | E8: 125 | F8: 0.48 | H8: =CONCATENATE($G$2,A8) -> 150006001500060061
A9: 1500060065 | B9: Bushing,Natural | C9: 0.15 | D9: 9 | E9: 400 | F9: 0.15 | H9: =CONCATENATE($G$2,A9) -> 150006001500060065
A10: 1500060070 | B10: Filtre,Mavi,Ön sinyal | C10: 0.67 | D10: 40.2 | E10: 89.552239 | F10: 0.67 | H10: =CONCATENATE($G$2,A10) -> 150006001500060070
A11: 1500060071 | B11: Filtre,Yesil,Arka sinyal | C11: 0.67 | D11: 40.2 | E11: 89.552239 | F11: 0.67 | H11: =CONCATENATE($G$2,A11) -> 150006001500060071
A12: 1500060072 | B12: Filtre,Kirmizi,Arka sinyal | C12: 1.65 | D12: 99 | E12: 36.363636 | F12: 1.65 | H12: =CONCATENATE($G$2,A12) -> 150006001500060072
A13: 1500060073 | B13: REFLEKTOR DRL TI H566 SOL | C13: 0.58 | D13: 34.8 | E13: 103.44828 | F13: 0.58 | H13: =CONCATENATE($G$2,A13) -> 150006001500060073
A14: 1500060074 | B14: REFLEKTOR DRL TI H566 SAG | C14: 0.58 | D14: 34.8 | E14: 103.44828 | F14: 0.58 | H14: =CONCATENATE($G$2,A14) -> 150006001500060074
... A20: 1500060080 | B20: IC LENS H566 SAG | C20: 0.62 | D20: 37.2 | E20: 96.774194 | F20: 0.62 | H20: =CONCATENATE($G$2,A20) -> 150006001500060080
A21: 1500060080 | B21: Ayar Mekanizmasi,Komple,Dikey | C21: 0 | D21: 0 | E21: #DIV/0! | F21: 0 | H21: =CONCATENATE($G$2,A21) -> 150006001500060080
A22: 1500060081 | B22: SIYAH BEZEL H566 SOL | C22: 0.83 | D22: 49.8 | E22: 72.289157 | F22: 0.83 | H22: =CONCATENATE($G$2,A22) -> 150006001500060081
A23: 1500060081 | B23: Ayar Mekanizması,Küçük,Komple | C23: 0 | D23: 0 | E23: #DIV/0! | F23: 0 | H23: =CONCATENATE($G$2,A23) -> 150006001500060081
A24: 1500060082 | B24: SIYAH BEZEL H566 SAG | C24: 0.83 | D24: 49.8 | E24: 72.289157 | F24: 0.83 | H24: =CONCATENATE($G$2,A24) -> 150006001500060082
A25: 1500060082 | B25: Ayar Mekanizması,Büyük,Komple | C25: 0 | D25: 0 | E25: #DIV/0! | F25: 0 | H25: =CONCATENATE($G$2,A25) -> 150006001500060082
A26: 1500060083 | B26: SIYAH BEZEL SIS H566 SOL | C26: 0.62 | D26: 37.2 | E26: 96.774194 | F26: 0.62 | H26: =CONCATENATE($G$2,A26) -> 150006001500060083
A27: 1500060083 | B27: Mercek Ünitesi,Komple | C27: 0 | D27: 0 | E27: #DIV/0! | F27: 0 | H27: =CONCATENATE($G$2,A27) -> 150006001500060083
A28: 1500060084 | B28: SIYAH BEZEL SIS H566 SAG | C28: 0.62 | D28: 37.2 | E28: 96.774194 | F28: 0.62 | H28: =CONCATENATE($G$2,A28) -> 150006001500060084
A29: 1500060084 | B29: Refl.Uzun Hüzme+Spot Komple | C29: 0 | D29: 0 | E29: #DIV/0! | F29: 0 | H29: =CONCATENATE($G$2,A29) -> 150006001500060084
A30: 1500060085 | B30: GOVDE H566 SOL HIGH | C30: 0.67 | D30: 40.2 | E30: 89.552239 | F30: 0.67 | H30: =CONCATENATE($G$2,A30) -> 150006001500060085
A31: 1500060086 | B31: GOVDE H566 SAG HIGH | C31: 0.67 | D31: 40.2 | E31: 89.552239 | F31: 0.67 | H31: =CONCATENATE($G$2,A31) -> 150006001500060086
A32: 1500060087 | B32: GOVDE H566 SOL BASE | C32: 0.67 | D32: 40.2 | E32: 89.552239 | F32: 0.67 | H32: =CONCATENATE($G$2,A32) -> 150006001500060087
A33: 1500060088 | B33: GOVDE H566 SAG BASE | C33: 0.67 | D33: 40.2 | E33: 89.552239 | F33: 0.67 | H33: =CONCATENATE($G$2,A33) -> 150006001500060088
A34: 1500060089 | B34: GOVDE SIS H566 SOL | C34: 0.62 | D34: 37.2 | E34: 96.774194 | F34: 0.62 | H34: =CONCATENATE($G$2,A34) -> 150006001500060089
A35: 1500060090 | B35: GOVDE SIS H566 SAG | C35: 0.62 | D35: 37.2 | E35: 96.774194 | F35: 0.62 | H35: =CONCATENATE($G$2,A35) -> 150006001500060090
A36: 1500060091 | B36: PES CERCEVE HIGH H566 SOL | C36: 0.54 | D36: 32.4 | E36: 111.11111 | F36: 0.54 | H36: =CONCATENATE($G$2,A36) -> 150006001500060091
A37: 1500060092 | B37: PES CERCEVE HIGH H566 SAG | C37: 0.54 | D37: 32.4 | E37: 111.11111 | F37: 0.54 | H37: =CONCATENATE($G$2,A37) -> 150006001500060092
A38: 1500060093 | B38: AYAR BRAKETI HIGH LOW 2 H566 | C38: 0.5 | D38: 30 | E38: 120 | F38: 0.5 | H38: =CONCATENATE($G$2,A38) -> 150006001500060093
A39: 1500060094 | B39: ARA ÇERÇEVE,SİYAH,SOL,H625 CARGO | C39: 1 | D39: 60 | E39: 60 | F39: 1 | H39: =CONCATENATE($G$2,A39) -> 150006001500060094
A40: 1500060095 | B40: ARA ÇERÇEVE,SİYAH,SAĞ,H625 CARGO | C40: 1 | D40: 60 | E40: 60 | F40: 1 | H40: =CONCATENATE($G$2,A40) -> 150006001500060095
A41: 1500060096 | B41: H625 KROM BEZEL SAG | C41: 1 | D41: 60 | E41: 60 | F41: 1 | H41: =CONCATENATE($G$2,A41) -> 150006001500060096
... A44: 1500060099 | B44: İÇ LENS,SAĞ,H625 CARGO | C44: 0.85 | D44: 51 | E44: 70.588235 | F44: 0.85 | H44: =CONCATENATE($G$2,A44) -> 150006001500060099
A45: 1500060100 | B45: REFLEKTÖR,SOL,DRL+TI,H625 CARGO | C45: 0.491 | D45: =60*C45 -> 29.46 | E45: =60/C45 -> 122.19959 | F45: 0.491 | G45: 1500060 | H45: =CONCATENATE($G$45,A45) -> 15000601500060100
A46: 1500060101 | B46: REFLEKTÖR,SAĞ,DRL+TI,H625 CARGO | C46: 0.491 | D46: =60*C46 -> 29.46 | E46: =60/C46 -> 122.19959 | F46: 0.491 | H46: =CONCATENATE($G$45,A46) -> 15000601500060101
A47: 1500060102 | B47: ARAÇERÇEVE,SOL,HIGH,H625 FAR BLACKLINE | C47: 1.05 | D47: =60*C47 -> 63 | E47: =60/C47 -> 57.142857 | F47: 1.05 | H47: =CONCATENATE($G$45,A47) -> 15000601500060102
...

Sheet ASAKAİ
A1: TARİH | B1: PLAN | C1: GERÇEKLEŞEN | D1: FİRE | E1: FİRE ORANI | F1: DURUŞ | G1: % | H1: Hurda Oranı %
A2: ='1'!A1 -> 46174 | B2: =IFERROR('1'!D63,0) -> 0 | C2: =IFERROR('1'!E63,0) -> 8900 | D2: =IFERROR('1'!F63,0) -> 111 | E2: =IFERROR('1'!G63,0) -> 12471.91 | F2: =IFERROR('1'!H63,0) -> 300 | G2: =IFERROR('1'!I63,0) -> 0 | H2: =IFERROR('1'!E46,0) -> 1.247191
A3: =A2+1 -> 46175 | B3: =IFERROR('2'!D63,0) -> 0 | C3: =IFERROR('2'!E63,0) -> 15480 | D3: =IFERROR('2'!F63,0) -> 111 | E3: =IFERROR('2'!G63,0) -> 7170.5426 | F3: =IFERROR('2'!H63,0) -> 180 | G3: =IFERROR('2'!I63,0) -> 0 | H3: =IFERROR('2'!E46,0) -> 0.71705426
A4: =A3+1 -> 46176 | B4: =IFERROR('3'!D63,0) -> 0 | C4: =IFERROR('3'!E63,0) -> 31629 | D4: =IFERROR('3'!F63,0) -> 324 | E4: =IFERROR('3'!G63,0) -> 10243.764 | F4: =IFERROR('3'!H63,0) -> 180 | G4: =IFERROR('3'!I63,0) -> 0 | H4: =IFERROR('3'!E46,0) -> 1.0243764
A5: =A4+1 -> 46177 | B5: =IFERROR('4'!D63,0) -> 0 | C5: =IFERROR('4'!E63,0) -> 10196 | D5: =IFERROR('4'!F63,0) -> 190 | E5: =IFERROR('4'!G63,0) -> 18634.759 | F5: =IFERROR('4'!H63,0) -> 180 | G5: =IFERROR('4'!I63,0) -> 0 | H5: =IFERROR('4'!E46,0) -> 1.8634759
A6: =A5+1 -> 46178 | B6: =IFERROR('5'!D63,0) -> 0 | C6: =IFERROR('5'!E63,0) -> 25475 | D6: =IFERROR('5'!F63,0) -> 96 | E6: =IFERROR('5'!G63,0) -> 3768.4004 | F6: =IFERROR('5'!H63,0) -> 0 | G6: =IFERROR('5'!I63,0) -> 0 | H6: =IFERROR('5'!E46,0) -> 0.37684004
A7: =A6+1 -> 46179 | B7: =IFERROR('6'!D63,0) -> 0 | C7: =IFERROR('6'!E63,0) -> 11855 | D7: =IFERROR('6'!F63,0) -> 120 | E7: =IFERROR('6'!G63,0) -> 10122.311 | F7: =IFERROR('6'!H63,0) -> 150 | G7: =IFERROR('6'!I63,0) -> 0 | H7: =IFERROR('6'!E46,0) -> 1.0122311
A8: =A7+1 -> 46180 | B8: =IFERROR('7'!D63,0) -> 0 | C8: =IFERROR('7'!E63,0) -> 20262 | D8: =IFERROR('7'!F63,0) -> 150 | E8: =IFERROR('7'!G63,0) -> 7403.0204 | F8: =IFERROR('7'!H63,0) -> 0 | G8: =IFERROR('7'!I63,0) -> 0 | H8: =IFERROR('7'!E46,0) -> 0.74030204
A9: =A8+1 -> 46181 | B9: =IFERROR('8'!D63,0) -> 0 | C9: =IFERROR('8'!E63,0) -> 12436 | D9: =IFERROR('8'!F63,0) -> 204 | E9: =IFERROR('8'!G63,0) -> 16403.988 | F9: =IFERROR('8'!H63,0) -> 150 | G9: =IFERROR('8'!I63,0) -> 0 | H9: =IFERROR('8'!E46,0) -> 1.6403988
A10: =A9+1 -> 46182 | B10: =IFERROR('9'!D63,0) -> 0 | C10: =IFERROR('9'!E63,0) -> 16027 | D10: =IFERROR('9'!F63,0) -> 252 | E10: =IFERROR('9'!G63,0) -> 15723.467 | F10: =IFERROR('9'!H63,0) -> 150 | G10: =IFERROR('9'!I63,0) -> 0 | H10: =IFERROR('9'!E46,0) -> 1.5723467
A11: =A10+1 -> 46183 | B11: =IFERROR('10'!D63,0) -> 0 | C11: =IFERROR('10'!E63,0) -> 29675 | D11: =IFERROR('10'!F63,0) -> 127 | E11: =IFERROR('10'!G63,0) -> 4279.6967 | F11: =IFERROR('10'!H63,0) -> 180 | G11: =IFERROR('10'!I63,0) -> 0 | H11: =IFERROR('10'!E46,0) -> 0.42796967
A12: =A11+1 -> 46184 | B12: =IFERROR('11'!D63,0) -> 0 | C12: =IFERROR('11'!E63,0) -> 8854 | D12: =IFERROR('11'!F63,0) -> 196 | E12: =IFERROR('11'!G63,0) -> 22136.887 | F12: =IFERROR('11'!H63,0) -> 120 | G12: =IFERROR('11'!I63,0) -> 0 | H12: =IFERROR('11'!E46,0) -> 2.2136887
A13: =A12+1 -> 46185 | B13: =IFERROR('12'!D63,0) -> 0 | C13: =IFERROR('12'!E63,0) -> 22840 | D13: =IFERROR('12'!F63,0) -> 223 | E13: =IFERROR('12'!G63,0) -> 9763.5727 | F13: =IFERROR('12'!H63,0) -> 120 | G13: =IFERROR('12'!I63,0) -> 0 | H13: =IFERROR('12'!E46,0) -> 0.97635727
A14: =A13+1 -> 46186 | B14: =IFERROR('13'!D63,0) -> 0 | C14: =IFERROR('13'!E63,0) -> 10462 | D14: =IFERROR('13'!F63,0) -> 216 | E14: =IFERROR('13'!G63,0) -> 20646.148 | F14: =IFERROR('13'!H63,0) -> 300 | G14: =IFERROR('13'!I63,0) -> 0 | H14: =IFERROR('13'!E46,0) -> 2.0646148
A15: =A14+1 -> 46187 | B15: =IFERROR('14'!D63,0) -> 0 | C15: =IFERROR('14'!E63,0) -> 9468 | D15: =IFERROR('14'!F63,0) -> 102 | E15: =IFERROR('14'!G63,0) -> 10773.131 | F15: =IFERROR('14'!H63,0) -> 0 | G15: =IFERROR('14'!I63,0) -> 0 | H15: =IFERROR('14'!E46,0) -> 1.0773131
A16: =A15+1 -> 46188 | B16: =IFERROR('15'!D63,0) -> 0 | C16: =IFERROR('15'!E63,0) -> 14505 | D16: =IFERROR('15'!F63,0) -> 119 | E16: =IFERROR('15'!G63,0) -> 8204.0676 | F16: =IFERROR('15'!H63,0) -> 175 | G16: =IFERROR('15'!I63,0) -> 0 | H16: =IFERROR('15'!E46,0) -> 0.82040676
A17: =A16+1 -> 46189 | B17: =IFERROR('16'!D63,0) -> 0 | C17: =IFERROR('16'!E63,0) -> 11692 | D17: =IFERROR('16'!F63,0) -> 106 | E17: =IFERROR('16'!G63,0) -> 9066.0281 | F17: =IFERROR('16'!H63,0) -> 180 | G17: =IFERROR('16'!I63,0) -> 0 | H17: =IFERROR('16'!E46,0) -> 0.90660281
A18: =A17+1 -> 46190 | B18: =IFERROR('17'!D63,0) -> 0 | C18: =IFERROR('17'!E63,0) -> 684 | D18: =IFERROR('17'!F63,0) -> 20 | E18: =IFERROR('17'!G63,0) -> 29239.766 | F18: =IFERROR('17'!H63,0) -> 0 | G18: =IFERROR('17'!I63,0) -> 0 | H18: =IFERROR('17'!E46,0) -> 2.9239766
A19: =A18+1 -> 46191 | B19: =IFERROR('18'!D63,0) -> 0 | C19: =IFERROR('18'!E63,0) -> 12976 | D19: =IFERROR('18'!F63,0) -> 137 | E19: =IFERROR('18'!G63,0) -> 10557.953 | F19: =IFERROR('18'!H63,0) -> 120 | G19: =IFERROR('18'!I63,0) -> 0 | H19: =IFERROR('18'!E46,0) -> 1.0557953
A20: =A19+1 -> 46192 | B20: =IFERROR('19'!D63,0) -> 0 | C20: =IFERROR('19'!E63,0) -> 27714 | D20: =IFERROR('19'!F63,0) -> 165 | E20: =IFERROR('19'!G63,0) -> 5953.6696 | F20: =IFERROR('19'!H63,0) -> 150 | G20: =IFERROR('19'!I63,0) -> 0 | H20: =IFERROR('19'!E46,0) -> 0.59536696
A21: =A20+1 -> 46193 | B21: =IFERROR('20'!D63,0) -> 0 | C21: =IFERROR('20'!E63,0) -> 25335 | D21: =IFERROR('20'!F63,0) -> 77 | E21: =IFERROR('20'!G63,0) -> 3039.2737 | F21: =IFERROR('20'!H63,0) -> 0 | G21: =IFERROR('20'!I63,0) -> 0 | H21: =IFERROR('20'!E46,0) -> 0.30392737
A22: =A21+1 -> 46194 | B22: =IFERROR('21'!D63,0) -> 0 | C22: =IFERROR('21'!E63,0) -> 15517 | D22: =IFERROR('21'!F63,0) -> 102 | E22: =IFERROR('21'!G63,0) -> 6573.4356 | F22: =IFERROR('21'!H63,0) -> 0 | G22: =IFERROR('21'!I63,0) -> 0 | H22: =IFERROR('21'!E46,0) -> 0.65734356
A23: =A22+1 -> 46195 | B23: =IFERROR('22'!D63,0) -> 0 | C23: =IFERROR('22'!E63,0) -> 23408 | D23: =IFERROR('22'!F63,0) -> 135 | E23: =IFERROR('22'!G63,0) -> 5767.2591 | F23: =IFERROR('22'!H63,0) -> 110 | G23: =IFERROR('22'!I63,0) -> 0 | H23: =IFERROR('22'!E46,0) -> 0.57672591
A24: =A23+1 -> 46196 | B24: =IFERROR('23'!D63,0) -> 0 | C24: =IFERROR('23'!E63,0) -> 12462 | D24: =IFERROR('23'!F63,0) -> 156 | E24: =IFERROR('23'!G63,0) -> 12518.055 | F24: =IFERROR('23'!H63,0) -> 400 | G24: =IFERROR('23'!I63,0) -> 0 | H24: =IFERROR('23'!E46,0) -> 1.2518055
A25: =A24+1 -> 46197 | B25: =IFERROR('24'!D63,0) -> 0 | C25: =IFERROR('24'!E63,0) -> 9488 | D25: =IFERROR('24'!F63,0) -> 200 | E25: =IFERROR('24'!G63,0) -> 21079.258 | F25: =IFERROR('24'!H63,0) -> 500 | G25: =IFERROR('24'!I63,0) -> 0 | H25: =IFERROR('24'!E46,0) -> 2.1079258
A26: =A25+1 -> 46198 | B26: =IFERROR('25'!D63,0) -> 0 | C26: =IFERROR('25'!E63,0) -> 8146 | D26: =IFERROR('25'!F63,0) -> 144 | E26: =IFERROR('25'!G63,0) -> 17677.388 | F26: =IFERROR('25'!H63,0) -> 400 | G26: =IFERROR('25'!I63,0) -> 0 | H26: =IFERROR('25'!E46,0) -> 1.7677388
A27: =A26+1 -> 46199 | B27: =IFERROR('26'!D63,0) -> 0 | C27: =IFERROR('26'!E63,0) -> 21794 | D27: =IFERROR('26'!F63,0) -> 346 | E27: =IFERROR('26'!G63,0) -> 15875.929 | F27: =IFERROR('26'!H63,0) -> 0 | G27: =IFERROR('26'!I63,0) -> 0 | H27: =IFERROR('26'!E46,0) -> 1.5875929
A28: =A27+1 -> 46200 | B28: =IFERROR('27'!D63,0) -> 0 | C28: =IFERROR('27'!E63,0) -> 0 | D28: =IFERROR('27'!F63,0) -> 0 | E28: =IFERROR('27'!G63,0) -> 0 | F28: =IFERROR('27'!H63,0) -> 0 | G28: =IFERROR('27'!I63,0) -> 0 | H28: =IFERROR('27'!E46,0) -> 0
A29: =A28+1 -> 46201 | B29: =IFERROR('28'!D63,0) -> 0 | C29: =IFERROR('28'!E63,0) -> 0 | D29: =IFERROR('28'!F63,0) -> 0 | E29: =IFERROR('28'!G63,0) -> 0 | F29: =IFERROR('28'!H63,0) -> 0 | G29: =IFERROR('28'!I63,0) -> 0 | H29: =IFERROR('28'!E46,0) -> 0
A30: =A29+1 -> 46202 | B30: =IFERROR('29'!D63,0) -> 0 | C30: =IFERROR('29'!E63,0) -> 18386 | D30: =IFERROR('29'!F63,0) -> 131 | E30: =IFERROR('29'!G63,0) -> 7124.9864 | F30: =IFERROR('29'!H63,0) -> 550 | G30: =IFERROR('29'!I63,0) -> 0 | H30: =IFERROR('29'!E46,0) -> 0.71249864
A31: =A30+1 -> 46203 | B31: =IFERROR('30'!D63,0) -> 0 | C31: =IFERROR('30'!E63,0) -> 13934 | D31: =IFERROR('30'!F63,0) -> 383 | E31: =IFERROR('30'!G63,0) -> 27486.723 | F31: =IFERROR('30'!H63,0) -> 0 | G31: =IFERROR('30'!I63,0) -> 0 | H31: =IFERROR('30'!E46,0) -> 2.7486723
A32: =A31+1 -> 46204 | B32: =IFERROR('31'!D63,0) -> 0 | C32: =IFERROR('31'!E63,0) -> 19032 | D32: =IFERROR('31'!F63,0) -> 147 | E32: =IFERROR('31'!G63,0) -> 7723.8335 | F32: =IFERROR('31'!H63,0) -> 0 | G32: =IFERROR('31'!I63,0) -> 0 | H32: =IFERROR('31'!E46,0) -> 0.77238335
A33: Toplam | B33: =SUM(B2:B32) -> 0 | C33: =SUM(C2:C32) -> 468632 | D33: =SUM(D2:D32) -> 4790 | E33: =SUM(E2:E32) -> 357429.22 | F33: =SUM(F2:F32) -> 4595 | G33: =SUM(G2:G32)/(COUNTIF(G2:G32,">0")) -> #DIV/0! | H33: =AVERAGE(H2:H32) -> 1.1529975

Sheet Sayfa2
A1: Malzeme | B1: Malzeme Açıklaması | C1: Oluşturulma Tarihi | D1: Belge Tarihi | E1: Env.Belge Tipi | F1: Hareket Yönü | G1: Stk.Tipi | H1: Stok Miktar | I1: Stok Birimi | J1: Oluşturan
A2: 150060283 | B2: 405 B, BRAKET A SOL AVRUPA | C2: 44967.399 | D2: 44967 | E2: OR | F2: Giriş | G2: Kullanılabilir | H2: 20 | I2: AD | J2: IASBATCH
A3: 150060283 | B3: 405 B, BRAKET A SOL AVRUPA | C3: 44967.399 | D3: 44967 | E3: OR | F3: Giriş | G3: Kullanılabilir | H3: 20 | I3: AD | J3: IASBATCH
A4: 150060283 | B4: 405 B, BRAKET A SOL AVRUPA | C4: 44967.399 | D4: 44967 | E4: OR | F4: Giriş | G4: Kullanılabilir | H4: 20 | I4: AD | J4: IASBATCH
A5: 150060283 | B5: 405 B, BRAKET A SOL AVRUPA | C5: 44967.399 | D5: 44967 | E5: OR | F5: Giriş | G5: Kullanılabilir | H5: 15 | I5: AD | J5: IASBATCH
A6: 150060283 | B6: 405 B, BRAKET A SOL AVRUPA | C6: 44967.416 | D6: 44967 | E6: OR | F6: Giriş | G6: Kullanılabilir | H6: 20 | I6: AD | J6: IASBATCH
A7: 150060283 | B7: 405 B, BRAKET A SOL AVRUPA | C7: 44967.447 | D7: 44967 | E7: OR | F7: Giriş | G7: Kullanılabilir | H7: 20 | I7: AD | J7: IASBATCH
A8: 150060283 | B8: 405 B, BRAKET A SOL AVRUPA | C8: 44967.447 | D8: 44967 | E8: OR | F8: Giriş | G8: Kullanılabilir | H8: 20 | I8: AD | J8: IASBATCH
A9: 150060283 | B9: 405 B, BRAKET A SOL AVRUPA | C9: 44967.447 | D9: 44967 | E9: OR | F9: Giriş | G9: Kullanılabilir | H9: 20 | I9: AD | J9: IASBATCH
A10: 150060283 | B10: 405 B, BRAKET A SOL AVRUPA | C10: 44967.471 | D10: 44967 | E10: OR | F10: Giriş | G10: Kullanılabilir | H10: 20 | I10: AD | J10: IASBATCH
A11: 150060283 | B11: 405 B, BRAKET A SOL AVRUPA | C11: 44967.471 | D11: 44967 | E11: OR | F11: Giriş | G11: Kullanılabilir | H11: 20 | I11: AD | J11: IASBATCH
A12: 150060283 | B12: 405 B, BRAKET A SOL AVRUPA | C12: 44967.489 | D12: 44967 | E12: OR | F12: Giriş | G12: Kullanılabilir | H12: 20 | I12: AD | J12: IASBATCH
A13: 150060283 | B13: 405 B, BRAKET A SOL AVRUPA | C13: 44967.496 | D13: 44967 | E13: OR | F13: Giriş | G13: Kullanılabilir | H13: 20 | I13: AD | J13: IASBATCH
... A256: 150061858 | B256: Lens 3500 LED SML/SRS WAAGR | C256: 44967.746 | D256: 44967 | E256: OR | F256: Giriş | G256: Kullanılabilir | H256: 192 | I256: AD | J256: IASBATCH

Sheet 1
A1: 46174 | H1: Genel Verimlilik | N1: =E45/D51 -> #N/A | P1: ANA SAYFA
A2: =TEXT(A1,"gggg") -> Pazartesi
C3: TOPLAM ÜRETİM | D3: =D45 -> 8900
A4: S.No | B4: P. Kod | C4: Ürün Tanımı | D4: Ürt. Adt | E4: Std. Süre Dk | G4: SAP Rjm Fire Adt | H4: Fire % | I4: SAP Std Fire % | K4: Std T.Süresi (Dk) | L4: Gerçekleşen Toplam Süre | M4: Kayıp Zamanlar Toplamı | N4: Ürün Performansı | O4: İşçilik Performansı | P4: Açıklama
A5: 1 | B5: 76 | C5: =IF(ISBLANK(B5),"",VLOOKUP(B5,SÜRELER!$A:$B,2,FALSE)) -> #N/A | D5: 442 | E5: =IF(ISBLANK($B5),"0",VLOOKUP($B5,SÜRELER!$A:$C,3,FALSE))*(D5-F5) -> #N/A | F5: 36 | G5: =VLOOKUP(B5,'R.H.'!A$3:C$3974,3,FALSE)*D5/100 -> #N/A | H5: =F5/D5 -> 0.081447964 | I5: =VLOOKUP(B5,'R.H.'!A$3:C$3974,3,FALSE)/100 -> #N/A | J5: 1 | K5: =E5/J5 -> #N/A | L5: 370 | N5: =K5/L5 -> #N/A | O5: =K5/(L5-M5) -> #N/A
A6: 2 | B6: 75 | C6: =IF(ISBLANK(B6),"",VLOOKUP(B6,SÜRELER!$A:$B,2,FALSE)) -> #N/A | D6: 190 | E6: =IF(ISBLANK($B6),"0",VLOOKUP($B6,SÜRELER!$A:$C,3,FALSE))*(D6-F6) -> #N/A | F6: 8 | G6: =VLOOKUP(B6,'R.H.'!A$3:C$3974,3,FALSE)*D6/100 -> #N/A | H6: =F6/D6 -> 0.042105263 | I6: =VLOOKUP(B6,'R.H.'!A$3:C$3974,3,FALSE)/100 -> #N/A | J6: 1 | K6: =E6/J6 -> #N/A | L6: 170 | N6: =K6/L6 -> #N/A | O6: =K6/(L6-M6) -> #N/A | P6: KROM BEZEL İTİCİ PİM ARZASI
A7: 3 | B7: 89 | C7: =IF(ISBLANK(B7),"",VLOOKUP(B7,SÜRELER!$A:$B,2,FALSE)) -> #N/A | D7: 292 | E7: =IF(ISBLANK($B7),"0",VLOOKUP($B7,SÜRELER!$A:$C,3,FALSE))*(D7-F7) -> #N/A | F7: 4 | G7: =VLOOKUP(B7,'R.H.'!A$3:C$3974,3,FALSE)*D7/100 -> #N/A | H7: =F7/D7 -> 0.01369863 | I7: =VLOOKUP(B7,'R.H.'!A$3:C$3974,3,FALSE)/100 -> #N/A | J7: 1 | K7: =E7/J7 -> #N/A | L7: 200 | N7: =K7/L7 -> #N/A | O7: =K7/(L7-M7) -> #N/A | P7: H566 SİS GÖVDE KALIP MAÇA ARZASI
A8: 4 | B8: 90 | C8: =IF(ISBLANK(B8),"",VLOOKUP(B8,SÜRELER!$A:$B,2,FALSE)) -> #N/A | D8: 292 | E8: =IF(ISBLANK($B8),"0",VLOOKUP($B8,SÜRELER!$A:$C,3,FALSE))*(D8-F8) -> #N/A | F8: 4 | G8: =VLOOKUP(B8,'R.H.'!A$3:C$3974,3,FALSE)*D8/100 -> #N/A | H8: =F8/D8 -> 0.01369863 | I8: =VLOOKUP(B8,'R.H.'!A$3:C$3974,3,FALSE)/100 -> #N/A | J8: 1 | K8: =E8/J8 -> #N/A | L8: 200 | N8: =K8/L8 -> #N/A | O8: =K8/(L8-M8) -> #N/A
A9: 5 | B9: 200 | C9: =IF(ISBLANK(B9),"",VLOOKUP(B9,SÜRELER!$A:$B,2,FALSE)) -> #N/A | D9: =740+761 -> 1501 | E9: =IF(ISBLANK($B9),"0",VLOOKUP($B9,SÜRELER!$A:$C,3,FALSE))*(D9-F9) -> #N/A | F9: 5 | G9: =VLOOKUP(B9,'R.H.'!A$3:C$3974,3,FALSE)*D9/100 -> #N/A | H9: =F9/D9 -> 0.0033311126 | I9: =VLOOKUP(B9,'R.H.'!A$3:C$3974,3,FALSE)/100 -> #N/A | J9: 1 | K9: =E9/J9 -> #N/A | L9: 800 | N9: =K9/L9 -> #N/A | O9: =K9/(L9-M9) -> #N/A
A10: 6 | B10: 2077 | C10: =IF(ISBLANK(B10),"",VLOOKUP(B10,SÜRELER!$A:$B,2,FALSE)) -> #N/A | D10: 200 | E10: =IF(ISBLANK($B10),"0",VLOOKUP($B10,SÜRELER!$A:$C,3,FALSE))*(D10-F10) -> #N/A | F10: 0 | G10: =VLOOKUP(B10,'R.H.'!A$3:C$3974,3,FALSE)*D10/100 -> #N/A | H10: =F10/D10 -> 0 | I10: =VLOOKUP(B10,'R.H.'!A$3:C$3974,3,FALSE)/100 -> #N/A | J10: 1 | K10: =E10/J10 -> #N/A | L10: 205 | N10: =K10/L10 -> #N/A | O10: =K10/(L10-M10) -> #N/A
A11: 7 | B11: 1339 | C11: =IF(ISBLANK(B11),"",VLOOKUP(B11,SÜRELER!$A:$B,2,FALSE)) -> #N/A | D11: 50 | E11: =IF(ISBLANK($B11),"0",VLOOKUP($B11,SÜRELER!$A:$C,3,FALSE))*(D11-F11) -> #N/A | F11: 0 | G11: =VLOOKUP(B11,'R.H.'!A$3:C$3974,3,FALSE)*D11/100 -> #N/A | H11: =F11/D11 -> 0 | I11: =VLOOKUP(B11,'R.H.'!A$3:C$3974,3,FALSE)/100 -> #N/A | J11: 1 | K11: =E11/J11 -> #N/A | L11: 52 | N11: =K11/L11 -> #N/A | O11: =K11/(L11-M11) -> #N/A
A12: 8 | B12: 248 | C12: =IF(ISBLANK(B12),"",VLOOKUP(B12,SÜRELER!$A:$B,2,FALSE)) -> #N/A | D12: =99+495 -> 594 | E12: =IF(ISBLANK($B12),"0",VLOOKUP($B12,SÜRELER!$A:$C,3,FALSE))*(D12-F12) -> #N/A | F12: 0 | G12: =VLOOKUP(B12,'R.H.'!A$3:C$3974,3,FALSE)*D12/100 -> #N/A | H12: =F12/D12 -> 0 | I12: =VLOOKUP(B12,'R.H.'!A$3:C$3974,3,FALSE)/100 -> #N/A | J12: 0.5 | K12: =E12/J12 -> #N/A | L12: 560 | N12: =K12/L12 -> #N/A | O12: =K12/(L12-M12) -> #N/A
A13: 9 | B13: 249 | C13: =IF(ISBLANK(B13),"",VLOOKUP(B13,SÜRELER!$A:$B,2,FALSE)) -> #N/A | D13: 594 | E13: =IF(ISBLANK($B13),"0",VLOOKUP($B13,SÜRELER!$A:$C,3,FALSE))*(D13-F13) -> #N/A | F13: 0 | G13: =VLOOKUP(B13,'R.H.'!A$3:C$3974,3,FALSE)*D13/100 -> #N/A | H13: =F13/D13 -> 0 | I13: =VLOOKUP(B13,'R.H.'!A$3:C$3974,3,FALSE)/100 -> #N/A | J13: 0.5 | K13: =E13/J13 -> #N/A | L13: 560 | N13: =K13/L13 -> #N/A | O13: =K13/(L13-M13) -> #N/A
A14: 10 | B14: 712 | C14: =IF(ISBLANK(B14),"",VLOOKUP(B14,SÜRELER!$A:$B,2,FALSE)) -> #N/A | D14: =298+307 -> 605 | E14: =IF(ISBLANK($B14),"0",VLOOKUP($B14,SÜRELER!$A:$C,3,FALSE))*(D14-F14) -> #N/A | F14: 11 | G14: =VLOOKUP(B14,'R.H.'!A$3:C$3974,3,FALSE)*D14/100 -> #N/A | H14: =F14/D14 -> 0.018181818 | I14: =VLOOKUP(B14,'R.H.'!A$3:C$3974,3,FALSE)/100 -> #N/A | J14: 0.5 | K14: =E14/J14 -> #N/A | L14: 800 | N14: =K14/L14 -> #N/A | O14: =K14/(L14-M14) -> #N/A
A15: 11 | B15: 712 | C15: =IF(ISBLANK(B15),"",VLOOKUP(B15,SÜRELER!$A:$B,2,FALSE)) -> #N/A | D15: 605 | E15: =IF(ISBLANK($B15),"0",VLOOKUP($B15,SÜRELER!$A:$C,3,FALSE))*(D15-F15) -> #N/A | F15: 11 | G15: =VLOOKUP(B15,'R.H.'!A$3:C$3974,3,FALSE)*D15/100 -> #N/A | H15: =F15/D15 -> 0.018181818 | I15: =VLOOKUP(B15,'R.H.'!A$3:C$3974,3,FALSE)/100 -> #N/A | J15: 0.5 | K15: =E15/J15 -> #N/A | L15: 800 | N15: =K15/L15 -> #N/A | O15: =K15/(L15-M15) -> #N/A
A16: 12 | B16: 472 | C16: =IF(ISBLANK(B16),"",VLOOKUP(B16,SÜRELER!$A:$B,2,FALSE)) -> #N/A | D16: 168 | E16: =IF(ISBLANK($B16),"0",VLOOKUP($B16,SÜRELER!$A:$C,3,FALSE))*(D16-F16) -> #N/A | F16: 0 | G16: =VLOOKUP(B16,'R.H.'!A$3:C$3974,3,FALSE)*D16/100 -> #N/A | H16: =F16/D16 -> 0 | I16: =VLOOKUP(B16,'R.H.'!A$3:C$3974,3,FALSE)/100 -> #N/A | J16: 0.5 | K16: =E16/J16 -> #N/A | L16: 130 | N16: =K16/L16 -> #N/A | O16: =K16/(L16-M16) -> #N/A
A17: 13 | B17: 473 | C17: =IF(ISBLANK(B17),"",VLOOKUP(B17,SÜRELER!$A:$B,2,FALSE)) -> #N/A | D17: 168 | E17: =IF(ISBLANK($B17),"0",VLOOKUP($B17,SÜRELER!$A:$C,3,FALSE))*(D17-F17) -> #N/A | F17: 0 | G17: =VLOOKUP(B17,'R.H.'!A$3:C$3974,3,FALSE)*D17/100 -> #N/A | H17: =F17/D17 -> 0 | I17: =VLOOKUP(B17,'R.H.'!A$3:C$3974,3,FALSE)/100 -> #N/A | J17: 0.5 | K17: =E17/J17 -> #N/A | L17: 130 | N17: =K17/L17 -> #N/A | O17: =K17/(L17-M17) -> #N/A
A18: 14 | B18: 710 | C18: =IF(ISBLANK(B18),"",VLOOKUP(B18,SÜRELER!$A:$B,2,FALSE)) -> #N/A | D18: =169+339 -> 508 | E18: =IF(ISBLANK($B18),"0",VLOOKUP($B18,SÜRELER!$A:$C,3,FALSE))*(D18-F18) -> #N/A | F18: 4 | G18: =VLOOKUP(B18,'R.H.'!A$3:C$3974,3,FALSE)*D18/100 -> #N/A | H18: =F18/D18 -> 0.0078740157 | I18: =VLOOKUP(B18,'R.H.'!A$3:C$3974,3,FALSE)/100 -> #N/A | J18: 0.5 | K18: =E18/J18 -> #N/A | L18: 550 | N18: =K18/L18 -> #N/A | O18: =K18/(L18-M18) -> #N/A
A19: 15 | B19: 711 | C19: =IF(ISBLANK(B19),"",VLOOKUP(B19,SÜRELER!$A:$B,2,FALSE)) -> #N/A | D19: 508 | E19: =IF(ISBLANK($B19),"0",VLOOKUP($B19,SÜRELER!$A:$C,3,FALSE))*(D19-F19) -> #N/A | F19: 4 | G19: =VLOOKUP(B19,'R.H.'!A$3:C$3974,3,FALSE)*D19/100 -> #N/A | H19: =F19/D19 -> 0.0078740157 | I19: =VLOOKUP(B19,'R.H.'!A$3:C$3974,3,FALSE)/100 -> #N/A | J19: 0.5 | K19: =E19/J19 -> #N/A | L19: 550 | N19: =K19/L19 -> #N/A | O19: =K19/(L19-M19) -> #N/A
A20: 16 | B20: 2100 | C20: =IF(ISBLANK(B20),"",VLOOKUP(B20,SÜRELER!$A:$B,2,FALSE)) -> #N/A | D20: =46+232 -> 278 | E20: =IF(ISBLANK($B20),"0",VLOOKUP($B20,SÜRELER!$A:$C,3,FALSE))*(D20-F20) -> #N/A | F20: 8 | G20: =VLOOKUP(B20,'R.H.'!A$3:C$3974,3,FALSE)*D20/100 -> #N/A | H20: =F20/D20 -> 0.028776978 | I20: =VLOOKUP(B20,'R.H.'!A$3:C$3974,3,FALSE)/100 -> #N/A | J20: 0.5 | K20: =E20/J20 -> #N/A | L20: 330 | N20: =K20/L20 -> #N/A | O20: =K20/(L20-M20) -> #N/A
A21: 17 | B21: 2101 | C21: =IF(ISBLANK(B21),"",VLOOKUP(B21,SÜRELER!$A:$B,2,FALSE)) -> #N/A | D21: 278 | E21: =IF(ISBLANK($B21),"0",VLOOKUP($B21,SÜRELER!$A:$C,3,FALSE))*(D21-F21) -> #N/A | F21: 8 | G21: =VLOOKUP(B21,'R.H.'!A$3:C$3974,3,FALSE)*D21/100 -> #N/A | H21: =F21/D21 -> 0.028776978 | I21: =VLOOKUP(B21,'R.H.'!A$3:C$3974,3,FALSE)/100 -> #N/A | J21: 0.5 | K21: =E21/J21 -> #N/A | L21: 330 | N21: =K21/L21 -> #N/A | O21: =K21/(L21-M21) -> #N/A
A22: 18 | B22: 1131 | C22: =IF(ISBLANK(B22),"",VLOOKUP(B22,SÜRELER!$A:$B,2,FALSE)) -> #N/A | D22: 827 | E22: =IF(ISBLANK($B22),"0",VLOOKUP($B22,SÜRELER!$A:$C,3,FALSE))*(D22-F22) -> #N/A | F22: 8 | G22: =VLOOKUP(B22,'R.H.'!A$3:C$3974,3,FALSE)*D22/100 -> #N/A | H22: =F22/D22 -> 0.0096735187 | I22: =VLOOKUP(B22,'R.H.'!A$3:C$3974,3,FALSE)/100 -> #N/A | J22: 0.5 | K22: =E22/J22 -> #N/A | L22: 545 | N22: =K22/L22 -> #N/A | O22: =K22/(L22-M22) -> #N/A
A23: 19 | B23: 9110 | C23: =IF(ISBLANK(B23),"",VLOOKUP(B23,SÜRELER!$A:$B,2,FALSE)) -> #N/A | D23: 400 | E23: =IF(ISBLANK($B23),"0",VLOOKUP($B23,SÜRELER!$A:$C,3,FALSE))*(D23-F23) -> #N/A | F23: 0 | G23: =VLOOKUP(B23,'R.H.'!A$3:C$3974,3,FALSE)*D23/100 -> #N/A | H23: =F23/D23 -> 0 | I23: =VLOOKUP(B23,'R.H.'!A$3:C$3974,3,FALSE)/100 -> #N/A | J23: 0.5 | K23: =E23/J23 -> #N/A | L23: 330 | N23: =K23/L23 -> #N/A | O23: =K23/(L23-M23) -> #N/A
A24: 20 | B24: 9120 | C24: =IF(ISBLANK(B24),"",VLOOKUP(B24,SÜRELER!$A:$B,2,FALSE)) -> #N/A | D24: 400 | E24: =IF(ISBLANK($B24),"0",VLOOKUP($B24,SÜRELER!$A:$C,3,FALSE))*(D24-F24) -> #N/A | F24: 0 | G24: =VLOOKUP(B24,'R.H.'!A$3:C$3974,3,FALSE)*D24/100 -> #N/A | H24: =F24/D24 -> 0 | I24: =VLOOKUP(B24,'R.H.'!A$3:C$3974,3,FALSE)/100 -> #N/A | J24: 0.5 | K24: =E24/J24 -> #N/A | L24: 330 | N24: =K24/L24 -> #N/A | O24: =K24/(L24-M24) -> #N/A
A25: 21 | C25: =IF(ISBLANK(B25),"",VLOOKUP(B25,SÜRELER!$A:$B,2,FALSE)) | E25: =IF(ISBLANK($B25),"0",VLOOKUP($B25,SÜRELER!$A:$C,3,FALSE))*(D25-F25) -> 0 | G25: =VLOOKUP(B25,'R.H.'!A$3:C$3974,3,FALSE)*D25/100 -> #N/A | H25: =F25/D25 -> #DIV/0! | I25: =VLOOKUP(B25,'R.H.'!A$3:C$3974,3,FALSE)/100 -> #N/A | K25: =E25/J25 -> #DIV/0! | N25: =K25/L25 -> #DIV/0! | O25: =K25/(L25-M25) -> #DIV/0!
A26: 22 | C26: =IF(ISBLANK(B26),"",VLOOKUP(B26,SÜRELER!$A:$B,2,FALSE)) | E26: =IF(ISBLANK($B26),"0",VLOOKUP($B26,SÜRELER!$A:$C,3,FALSE))*(D26-F26) -> 0 | G26: =VLOOKUP(B26,'R.H.'!A$3:C$3974,3,FALSE)*D26/100 -> #N/A | H26: =F26/D26 -> #DIV/0! | I26: =VLOOKUP(B26,'R.H.'!A$3:C$3974,3,FALSE)/100 -> #N/A | K26: =E26/J26 -> #DIV/0! | N26: =K26/L26 -> #DIV/0! | O26: =K26/(L26-M26) -> #DIV/0!
A27: 23 | C27: =IF(ISBLANK(B27),"",VLOOKUP(B27,SÜRELER!$A:$B,2,FALSE)) | E27: =IF(ISBLANK($B27),"0",VLOOKUP($B27,SÜRELER!$A:$C,3,FALSE))*(D27-F27) -> 0 | G27: =VLOOKUP(B27,'R.H.'!A$3:C$3974,3,FALSE)*D27/100 -> #N/A | H27: =F27/D27 -> #DIV/0! | I27: =VLOOKUP(B27,'R.H.'!A$3:C$3974,3,FALSE)/100 -> #N/A | K27: =E27/J27 -> #DIV/0! | N27: =K27/L27 -> #DIV/0! | O27: =K27/(L27-M27) -> #DIV/0!
A28: 24 | C28: =IF(ISBLANK(B28),"",VLOOKUP(B28,SÜRELER!$A:$B,2,FALSE)) | E28: =IF(ISBLANK($B28),"0",VLOOKUP($B28,SÜRELER!$A:$C,3,FALSE))*(D28-F28) -> 0 | G28: =VLOOKUP(B28,'R.H.'!A$3:C$3974,3,FALSE)*D28/100 -> #N/A | H28: =F28/D28 -> #DIV/0! | I28: =VLOOKUP(B28,'R.H.'!A$3:C$3974,3,FALSE)/100 -> #N/A | K28: =E28/J28 -> #DIV/0! | N28: =K28/L28 -> #DIV/0! | O28: =K28/(L28-M28) -> #DIV/0!
A29: 25 | C29: =IF(ISBLANK(B29),"",VLOOKUP(B29,SÜRELER!$A:$B,2,FALSE)) | E29: =IF(ISBLANK($B29),"0",VLOOKUP($B29,SÜRELER!$A:$C,3,FALSE))*(D29-F29) -> 0 | G29: =VLOOKUP(B29,'R.H.'!A$3:C$3974,3,FALSE)*D29/100 -> #N/A | H29: =F29/D29 -> #DIV/0! | I29: =VLOOKUP(B29,'R.H.'!A$3:C$3974,3,FALSE)/100 -> #N/A | K29: =E29/J29 -> #DIV/0! | N29: =K29/L29 -> #DIV/0! | O29: =K29/(L29-M29) -> #DIV/0!
A30: 26 | C30: =IF(ISBLANK(B30),"",VLOOKUP(B30,SÜRELER!$A:$B,2,FALSE)) | E30: =IF(ISBLANK($B30),"0",VLOOKUP($B30,SÜRELER!$A:$C,3,FALSE))*(D30-F30) -> 0 | G30: =VLOOKUP(B30,'R.H.'!A$3:C$3974,3,FALSE)*D30/100 -> #N/A | H30: =F30/D30 -> #DIV/0! | I30: =VLOOKUP(B30,'R.H.'!A$3:C$3974,3,FALSE)/100 -> #N/A | K30: =E30/J30 -> #DIV/0! | N30: =K30/L30 -> #DIV/0! | O30: =K30/(L30-M30) -> #DIV/0!
A31: 27 | C31: =IF(ISBLANK(B31),"",VLOOKUP(B31,SÜRELER!$A:$B,2,FALSE)) | E31: =IF(ISBLANK($B31),"0",VLOOKUP($B31,SÜRELER!$A:$C,3,FALSE))*(D31-F31) -> 0 | G31: =VLOOKUP(B31,'R.H.'!A$3:C$3974,3,FALSE)*D31/100 -> #N/A | H31: =F31/D31 -> #DIV/0! | I31: =VLOOKUP(B31,'R.H.'!A$3:C$3974,3,FALSE)/100 -> #N/A | K31: =E31/J31 -> #DIV/0! | N31: =K31/L31 -> #DIV/0! | O31: =K31/(L31-M31) -> #DIV/0!
A32: 28 | C32: =IF(ISBLANK(B32),"",VLOOKUP(B32,SÜRELER!$A:$B,2,FALSE)) | E32: =IF(ISBLANK($B32),"0",VLOOKUP($B32,SÜRELER!$A:$C,3,FALSE))*(D32-F32) -> 0 | G32: =VLOOKUP(B32,'R.H.'!A$3:C$3974,3,FALSE)*D32/100 -> #N/A | H32: =F32/D32 -> #DIV/0! | I32: =VLOOKUP(B32,'R.H.'!A$3:C$3974,3,FALSE)/100 -> #N/A | K32: =E32/J32 -> #DIV/0! | N32: =K32/L32 -> #DIV/0! | O32: =K32/(L32-M32) -> #DIV/0!
A33: 29 | C33: =IF(ISBLANK(B33),"",VLOOKUP(B33,SÜRELER!$A:$B,2,FALSE)) | E33: =IF(ISBLANK($B33),"0",VLOOKUP($B33,SÜRELER!$A:$C,3,FALSE))*(D33-F33) -> 0 | G33: =VLOOKUP(B33,'R.H.'!A$3:C$3974,3,FALSE)*D33/100 -> #N/A | H33: =F33/D33 -> #DIV/0! | I33: =VLOOKUP(B33,'R.H.'!A$3:C$3974,3,FALSE)/100 -> #N/A | K33: =E33/J33 -> #DIV/0! | N33: =K33/L33 -> #DIV/0! | O33: =K33/(L33-M33) -> #DIV/0!
A34: 30 | C34: =IF(ISBLANK(B34),"",VLOOKUP(B34,SÜRELER!$A:$B,2,FALSE)) | E34: =IF(ISBLANK($B34),"0",VLOOKUP($B34,SÜRELER!$A:$C,3,FALSE))*(D34-F34) -> 0 | G34: =VLOOKUP(B34,'R.H.'!A$3:C$3974,3,FALSE)*D34/100 -> #N/A | H34: =F34/D34 -> #DIV/0! | I34: =VLOOKUP(B34,'R.H.'!A$3:C$3974,3,FALSE)/100 -> #N/A | K34: =E34/J34 -> #DIV/0! | N34: =K34/L34 -> #DIV/0! | O34: =K34/(L34-M34) -> #DIV/0!
A35: 31 | C35: =IF(ISBLANK(B35),"",VLOOKUP(B35,SÜRELER!$A:$B,2,FALSE)) | E35: =IF(ISBLANK($B35),"0",VLOOKUP($B35,SÜRELER!$A:$C,3,FALSE))*(D35-F35) -> 0 | G35: =VLOOKUP(B35,'R.H.'!A$3:C$3974,3,FALSE)*D35/100 -> #N/A | H35: =F35/D35 -> #DIV/0! | I35: =VLOOKUP(B35,'R.H.'!A$3:C$3974,3,FALSE)/100 -> #N/A | K35: =E35/J35 -> #DIV/0! | N35: =K35/L35 -> #DIV/0! | O35: =K35/(L35-M35) -> #DIV/0!
A36: 32 | C36: =IF(ISBLANK(B36),"",VLOOKUP(B36,SÜRELER!$A:$B,2,FALSE)) | E36: =IF(ISBLANK($B36),"0",VLOOKUP($B36,SÜRELER!$A:$C,3,FALSE))*(D36-F36) -> 0 | G36: =VLOOKUP(B36,'R.H.'!A$3:C$3974,3,FALSE)*D36/100 -> #N/A | H36: =F36/D36 -> #DIV/0! | I36: =VLOOKUP(B36,'R.H.'!A$3:C$3974,3,FALSE)/100 -> #N/A | K36: =E36/J36 -> #DIV/0! | N36: =K36/L36 -> #DIV/0! | O36: =K36/(L36-M36) -> #DIV/0!
... A44: 40 | C44: =IF(ISBLANK(B44),"",VLOOKUP(B44,SÜRELER!$A:$B,2,FALSE)) | E44: =IF(ISBLANK($B44),"0",VLOOKUP($B44,SÜRELER!$A:$C,3,FALSE))*(D44-F44) -> 0 | G44: =VLOOKUP(B44,'R.H.'!A$3:C$3974,3,FALSE)*D44/100 -> #N/A | H44: =F44/D44 -> #DIV/0! | I44: =VLOOKUP(B44,'R.H.'!A$3:C$3974,3,FALSE)/100 -> #N/A | K44: =E44/J44 -> #DIV/0! | N44: =K44/L44 -> #DIV/0! | O44: =K44/(L44-M44) -> #DIV/0!
D45: =SUM(D5:D44) -> 8900 | E45: =SUM(E5:E44) -> #N/A | F45: =SUM(F5:F44) -> 111 | L45: =SUM(L5:L44) -> 7942 | M45: =SUM(M5:M44) -> 0
D46: % | E46: =F45/D45*100 -> 1.247191
C49: Eleman Sayısı : | D49: 4
...

Sheet 2
A1: 46205 | H1: Genel Verimlilik | N1: =E45/D51 -> #N/A | P1: ANA SAYFA
A2: =TEXT(A1,"gggg") -> Perşembe
C3: TOPLAM ÜRETİM | D3: =D45 -> 15480
A4: S.No | B4: P. Kod | C4: Ürün Tanımı | D4: Ürt. Adt | E4: Std. Süre Dk | G4: SAP Rjm Fire Adt | H4: Fire % | I4: SAP Std Fire % | K4: Std T.Süresi (Dk) | L4: Gerçekleşen Toplam Süre | M4: Kayıp Zamanlar Toplamı | N4: Ürün Performansı | O4: İşçilik Performansı | P4: Açıklama
A5: 1 | B5: 76 | C5: =IF(ISBLANK(B5),"",VLOOKUP(B5,SÜRELER!$A:$B,2,FALSE)) -> #N/A | D5: 406 | E5: =IF(ISBLANK($B5),"0",VLOOKUP($B5,SÜRELER!$A:$C,3,FALSE))*(D5-F5) -> #N/A | F5: 10 | G5: =VLOOKUP(B5,'R.H.'!A$3:C$3974,3,FALSE)*D5/100 -> #N/A | H5: =F5/D5 -> 0.024630542 | I5: =VLOOKUP(B5,'R.H.'!A$3:C$3974,3,FALSE)/100 -> #N/A | J5: 1 | K5: =E5/J5 -> #N/A | L5: 340 | N5: =K5/L5 -> #N/A | O5: =K5/(L5-M5) -> #N/A
A6: 2 | B6: 75 | C6: =IF(ISBLANK(B6),"",VLOOKUP(B6,SÜRELER!$A:$B,2,FALSE)) -> #N/A | D6: 336 | E6: =IF(ISBLANK($B6),"0",VLOOKUP($B6,SÜRELER!$A:$C,3,FALSE))*(D6-F6) -> #N/A | F6: 6 | G6: =VLOOKUP(B6,'R.H.'!A$3:C$3974,3,FALSE)*D6/100 -> #N/A | H6: =F6/D6 -> 0.017857143 | I6: =VLOOKUP(B6,'R.H.'!A$3:C$3974,3,FALSE)/100 -> #N/A | J6: 1 | K6: =E6/J6 -> #N/A | L6: 280 | N6: =K6/L6 -> #N/A | O6: =K6/(L6-M6) -> #N/A
A7: 3 | B7: 2076 | C7: =IF(ISBLANK(B7),"",VLOOKUP(B7,SÜRELER!$A:$B,2,FALSE)) -> #N/A | D7: 1990 | E7: =IF(ISBLANK($B7),"0",VLOOKUP($B7,SÜRELER!$A:$C,3,FALSE))*(D7-F7) -> #N/A | F7: 5 | G7: =VLOOKUP(B7,'R.H.'!A$3:C$3974,3,FALSE)*D7/100 -> #N/A | H7: =F7/D7 -> 0.0025125628 | I7: =VLOOKUP(B7,'R.H.'!A$3:C$3974,3,FALSE)/100 -> #N/A | J7: 1 | K7: =E7/J7 -> #N/A | L7: 1180 | N7: =K7/L7 -> #N/A | O7: =K7/(L7-M7) -> #N/A
A8: 4 | B8: 248 | C8: =IF(ISBLANK(B8),"",VLOOKUP(B8,SÜRELER!$A:$B,2,FALSE)) -> #N/A | D8: 972 | E8: =IF(ISBLANK($B8),"0",VLOOKUP($B8,SÜRELER!$A:$C,3,FALSE))*(D8-F8) -> #N/A | F8: 0 | G8: =VLOOKUP(B8,'R.H.'!A$3:C$3974,3,FALSE)*D8/100 -> #N/A | H8: =F8/D8 -> 0 | I8: =VLOOKUP(B8,'R.H.'!A$3:C$3974,3,FALSE)/100 -> #N/A | J8: 0.5 | K8: =E8/J8 -> #N/A | L8: 935 | N8: =K8/L8 -> #N/A | O8: =K8/(L8-M8) -> #N/A
A9: 5 | B9: 249 | C9: =IF(ISBLANK(B9),"",VLOOKUP(B9,SÜRELER!$A:$B,2,FALSE)) -> #N/A | D9: 972 | E9: =IF(ISBLANK($B9),"0",VLOOKUP($B9,SÜRELER!$A:$C,3,FALSE))*(D9-F9) -> #N/A | F9: 0 | G9: =VLOOKUP(B9,'R.H.'!A$3:C$3974,3,FALSE)*D9/100 -> #N/A | H9: =F9/D9 -> 0 | I9: =VLOOKUP(B9,'R.H.'!A$3:C$3974,3,FALSE)/100 -> #N/A | J9: 0.5 | K9: =E9/J9 -> #N/A | L9: 935 | N9: =K9/L9 -> #N/A | O9: =K9/(L9-M9) -> #N/A
A10: 6 | B10: 742 | C10: =IF(ISBLANK(B10),"",VLOOKUP(B10,SÜRELER!$A:$B,2,FALSE)) -> #N/A | D10: =394+50 -> 444 | E10: =IF(ISBLANK($B10),"0",VLOOKUP($B10,SÜRELER!$A:$C,3,FALSE))*(D10-F10) -> #N/A | F10: 0 | G10: =VLOOKUP(B10,'R.H.'!A$3:C$3974,3,FALSE)*D10/100 -> #N/A | H10: =F10/D10 -> 0 | I10: =VLOOKUP(B10,'R.H.'!A$3:C$3974,3,FALSE)/100 -> #N/A | J10: 0.5 | K10: =E10/J10 -> #N/A | L10: 380 | N10: =K10/L10 -> #N/A | O10: =K10/(L10-M10) -> #N/A
A11: 7 | B11: 743 | C11: =IF(ISBLANK(B11),"",VLOOKUP(B11,SÜRELER!$A:$B,2,FALSE)) -> #N/A | D11: 444 | E11: =IF(ISBLANK($B11),"0",VLOOKUP($B11,SÜRELER!$A:$C,3,FALSE))*(D11-F11) -> #N/A | F11: 0 | G11: =VLOOKUP(B11,'R.H.'!A$3:C$3974,3,FALSE)*D11/100 -> #N/A | H11: =F11/D11 -> 0 | I11: =VLOOKUP(B11,'R.H.'!A$3:C$3974,3,FALSE)/100 -> #N/A | J11: 0.5 | K11: =E11/J11 -> #N/A | L11: 380 | N11: =K11/L11 -> #N/A | O11: =K11/(L11-M11) -> #N/A
A12: 8 | B12: 9110 | C12: =IF(ISBLANK(B12),"",VLOOKUP(B12,SÜRELER!$A:$B,2,FALSE)) -> #N/A | D12: 300 | E12: =IF(ISBLANK($B12),"0",VLOOKUP($B12,SÜRELER!$A:$C,3,FALSE))*(D12-F12) -> #N/A | F12: 0 | G12: =VLOOKUP(B12,'R.H.'!A$3:C$3974,3,FALSE)*D12/100 -> #N/A | H12: =F12/D12 -> 0 | I12: =VLOOKUP(B12,'R.H.'!A$3:C$3974,3,FALSE)/100 -> #N/A | J12: 2 | K12: =E12/J12 -> #N/A | L12: 80 | N12: =K12/L12 -> #N/A | O12: =K12/(L12-M12) -> #N/A | P12: W204 EKT SENSÖR ARZASI
A13: 9 | B13: 9120 | C13: =IF(ISBLANK(B13),"",VLOOKUP(B13,SÜRELER!$A:$B,2,FALSE)) -> #N/A | D13: 300 | E13: =IF(ISBLANK($B13),"0",VLOOKUP($B13,SÜRELER!$A:$C,3,FALSE))*(D13-F13) -> #N/A | F13: 0 | G13: =VLOOKUP(B13,'R.H.'!A$3:C$3974,3,FALSE)*D13/100 -> #N/A | H13: =F13/D13 -> 0 | I13: =VLOOKUP(B13,'R.H.'!A$3:C$3974,3,FALSE)/100 -> #N/A | J13: 2 | K13: =E13/J13 -> #N/A | L13: 80 | N13: =K13/L13 -> #N/A | O13: =K13/(L13-M13) -> #N/A
A14: 10 | B14: 1908 | C14: =IF(ISBLANK(B14),"",VLOOKUP(B14,SÜRELER!$A:$B,2,FALSE)) -> #N/A | D14: 1024 | E14: =IF(ISBLANK($B14),"0",VLOOKUP($B14,SÜRELER!$A:$C,3,FALSE))*(D14-F14) -> #N/A | F14: 0 | G14: =VLOOKUP(B14,'R.H.'!A$3:C$3974,3,FALSE)*D14/100 -> #N/A | H14: =F14/D14 -> 0 | I14: =VLOOKUP(B14,'R.H.'!A$3:C$3974,3,FALSE)/100 -> #N/A | J14: 0.5 | K14: =E14/J14 -> #N/A | L14: 1195 | N14: =K14/L14 -> #N/A | O14: =K14/(L14-M14) -> #N/A
A15: 11 | B15: 1909 | C15: =IF(ISBLANK(B15),"",VLOOKUP(B15,SÜRELER!$A:$B,2,FALSE)) -> #N/A | D15: 1024 | E15: =IF(ISBLANK($B15),"0",VLOOKUP($B15,SÜRELER!$A:$C,3,FALSE))*(D15-F15) -> #N/A | F15: 0 | G15: =VLOOKUP(B15,'R.H.'!A$3:C$3974,3,FALSE)*D15/100 -> #N/A | H15: =F15/D15 -> 0 | I15: =VLOOKUP(B15,'R.H.'!A$3:C$3974,3,FALSE)/100 -> #N/A | J15: 0.5 | K15: =E15/J15 -> #N/A | L15: 1195 | N15: =K15/L15 -> #N/A | O15: =K15/(L15-M15) -> #N/A
A16: 12 | B16: 2189 | C16: =IF(ISBLANK(B16),"",VLOOKUP(B16,SÜRELER!$A:$B,2,FALSE)) -> #N/A | D16: =325+96 -> 421 | E16: =IF(ISBLANK($B16),"0",VLOOKUP($B16,SÜRELER!$A:$C,3,FALSE))*(D16-F16) -> #N/A | F16: 12 | G16: =VLOOKUP(B16,'R.H.'!A$3:C$3974,3,FALSE)*D16/100 -> #N/A | H16: =F16/D16 -> 0.028503563 | I16: =VLOOKUP(B16,'R.H.'!A$3:C$3974,3,FALSE)/100 -> #N/A | J16: 0.5 | K16: =E16/J16 -> #N/A | L16: 250 | N16: =K16/L16 -> #N/A | O16: =K16/(L16-M16) -> #N/A
A17: 13 | B17: 2190 | C17: =IF(ISBLANK(B17),"",VLOOKUP(B17,SÜRELER!$A:$B,2,FALSE)) -> #N/A | D17: 421 | E17: =IF(ISBLANK($B17),"0",VLOOKUP($B17,SÜRELER!$A:$C,3,FALSE))*(D17-F17) -> #N/A | F17: 12 | G17: =VLOOKUP(B17,'R.H.'!A$3:C$3974,3,FALSE)*D17/100 -> #N/A | H17: =F17/D17 -> 0.028503563 | I17: =VLOOKUP(B17,'R.H.'!A$3:C$3974,3,FALSE)/100 -> #N/A | J17: 0.5 | K17: =E17/J17 -> #N/A | L17: 250 | N17: =K17/L17 -> #N/A | O17: =K17/(L17-M17) -> #N/A
A18: 14 | B18: 2191 | C18: =IF(ISBLANK(B18),"",VLOOKUP(B18,SÜRELER!$A:$B,2,FALSE)) -> #N/A | D18: 421 | E18: =IF(ISBLANK($B18),"0",VLOOKUP($B18,SÜRELER!$A:$C,3,FALSE))*(D18-F18) -> #N/A | F18: 12 | G18: =VLOOKUP(B18,'R.H.'!A$3:C$3974,3,FALSE)*D18/100 -> #N/A | H18: =F18/D18 -> 0.028503563 | I18: =VLOOKUP(B18,'R.H.'!A$3:C$3974,3,FALSE)/100 -> #N/A | J18: 0.5 | K18: =E18/J18 -> #N/A | L18: 250 | N18: =K18/L18 -> #N/A | O18: =K18/(L18-M18) -> #N/A
A19: 15 | B19: 2192 | C19: =IF(ISBLANK(B19),"",VLOOKUP(B19,SÜRELER!$A:$B,2,FALSE)) -> #N/A | D19: 421 | E19: =IF(ISBLANK($B19),"0",VLOOKUP($B19,SÜRELER!$A:$C,3,FALSE))*(D19-F19) -> #N/A | F19: 12 | G19: =VLOOKUP(B19,'R.H.'!A$3:C$3974,3,FALSE)*D19/100 -> #N/A | H19: =F19/D19 -> 0.028503563 | I19: =VLOOKUP(B19,'R.H.'!A$3:C$3974,3,FALSE)/100 -> #N/A | J19: 0.5 | K19: =E19/J19 -> #N/A | L19: 250 | N19: =K19/L19 -> #N/A | O19: =K19/(L19-M19) -> #N/A
A20: 16 | B20: 2080 | C20: =IF(ISBLANK(B20),"",VLOOKUP(B20,SÜRELER!$A:$B,2,FALSE)) -> #N/A | D20: =984+420 -> 1404 | E20: =IF(ISBLANK($B20),"0",VLOOKUP($B20,SÜRELER!$A:$C,3,FALSE))*(D20-F20) -> #N/A | F20: 4 | G20: =VLOOKUP(B20,'R.H.'!A$3:C$3974,3,FALSE)*D20/100 -> #N/A | H20: =F20/D20 -> 0.0028490028 | I20: =VLOOKUP(B20,'R.H.'!A$3:C$3974,3,FALSE)/100 -> #N/A | J20: 1 | K20: =E20/J20 -> #N/A | L20: 1060 | N20: =K20/L20 -> #N/A | O20: =K20/(L20-M20) -> #N/A
A21: 17 | B21: 2078 | C21: =IF(ISBLANK(B21),"",VLOOKUP(B21,SÜRELER!$A:$B,2,FALSE)) -> #N/A | D21: 800 | E21: =IF(ISBLANK($B21),"0",VLOOKUP($B21,SÜRELER!$A:$C,3,FALSE))*(D21-F21) -> #N/A | F21: 0 | G21: =VLOOKUP(B21,'R.H.'!A$3:C$3974,3,FALSE)*D21/100 -> #N/A | H21: =F21/D21 -> 0 | I21: =VLOOKUP(B21,'R.H.'!A$3:C$3974,3,FALSE)/100 -> #N/A | J21: 0.5 | K21: =E21/J21 -> #N/A | L21: 1610 | N21: =K21/L21 -> #N/A | O21: =K21/(L21-M21) -> #N/A
A22: 18 | B22: 683 | C22: =IF(ISBLANK(B22),"",VLOOKUP(B22,SÜRELER!$A:$B,2,FALSE)) -> #N/A | D22: =110+250 -> 360 | E22: =IF(ISBLANK($B22),"0",VLOOKUP($B22,SÜRELER!$A:$C,3,FALSE))*(D22-F22) -> #N/A | F22: 8 | G22: =VLOOKUP(B22,'R.H.'!A$3:C$3974,3,FALSE)*D22/100 -> #N/A | H22: =F22/D22 -> 0.022222222 | I22: =VLOOKUP(B22,'R.H.'!A$3:C$3974,3,FALSE)/100 -> #N/A | J22: 0.5 | K22: =E22/J22 -> #N/A | L22: 710 | N22: =K22/L22 -> #N/A | O22: =K22/(L22-M22) -> #N/A
A23: 19 | B23: 2070 | C23: =IF(ISBLANK(B23),"",VLOOKUP(B23,SÜRELER!$A:$B,2,FALSE)) -> #N/A | D23: =442+278 -> 720 | E23: =IF(ISBLANK($B23),"0",VLOOKUP($B23,SÜRELER!$A:$C,3,FALSE))*(D23-F23) -> #N/A | F23: 0 | G23: =VLOOKUP(B23,'R.H.'!A$3:C$3974,3,FALSE)*D23/100 -> #N/A | H23: =F23/D23 -> 0 | I23: =VLOOKUP(B23,'R.H.'!A$3:C$3974,3,FALSE)/100 -> #N/A | J23: 0.5 | K23: =E23/J23 -> #N/A | L23: 700 | N23: =K23/L23 -> #N/A | O23: =K23/(L23-M23) -> #N/A | P23: S310 TRP TIRNAK KALMA PROPLEMİ
A24: 20 | B24: 2071 | C24: =IF(ISBLANK(B24),"",VLOOKUP(B24,SÜRELER!$A:$B,2,FALSE)) -> #N/A | D24: 720 | E24: =IF(ISBLANK($B24),"0",VLOOKUP($B24,SÜRELER!$A:$C,3,FALSE))*(D24-F24) -> #N/A | F24: 0 | G24: =VLOOKUP(B24,'R.H.'!A$3:C$3974,3,FALSE)*D24/100 -> #N/A | H24: =F24/D24 -> 0 | I24: =VLOOKUP(B24,'R.H.'!A$3:C$3974,3,FALSE)/100 -> #N/A | J24: 0.5 | K24: =E24/J24 -> #N/A | L24: 700 | N24: =K24/L24 -> #N/A | O24: =K24/(L24-M24) -> #N/A
A25: 21 | B25: 2102 | C25: =IF(ISBLANK(B25),"",VLOOKUP(B25,SÜRELER!$A:$B,2,FALSE)) -> #N/A | D25: =248+50 -> 298 | E25: =IF(ISBLANK($B25),"0",VLOOKUP($B25,SÜRELER!$A:$C,3,FALSE))*(D25-F25) -> #N/A | F25: 10 | G25: =VLOOKUP(B25,'R.H.'!A$3:C$3974,3,FALSE)*D25/100 -> #N/A | H25: =F25/D25 -> 0.033557047 | I25: =VLOOKUP(B25,'R.H.'!A$3:C$3974,3,FALSE)/100 -> #N/A | J25: 0.5 | K25: =E25/J25 -> #N/A | L25: 580 | N25: =K25/L25 -> #N/A | O25: =K25/(L25-M25) -> #N/A
A26: 22 | B26: 2103 | C26: =IF(ISBLANK(B26),"",VLOOKUP(B26,SÜRELER!$A:$B,2,FALSE)) -> #N/A | D26: 298 | E26: =IF(ISBLANK($B26),"0",VLOOKUP($B26,SÜRELER!$A:$C,3,FALSE))*(D26-F26) -> #N/A | F26: 10 | G26: =VLOOKUP(B26,'R.H.'!A$3:C$3974,3,FALSE)*D26/100 -> #N/A | H26: =F26/D26 -> 0.033557047 | I26: =VLOOKUP(B26,'R.H.'!A$3:C$3974,3,FALSE)/100 -> #N/A | J26: 0.5 | K26: =E26/J26 -> #N/A | L26: 580 | N26: =K26/L26 -> #N/A | O26: =K26/(L26-M26) -> #N/A
A27: 23 | B27: 1112 | C27: =IF(ISBLANK(B27),"",VLOOKUP(B27,SÜRELER!$A:$B,2,FALSE)) -> #N/A | D27: 400 | E27: =IF(ISBLANK($B27),"0",VLOOKUP($B27,SÜRELER!$A:$C,3,FALSE))*(D27-F27) -> #N/A | F27: 0 | G27: =VLOOKUP(B27,'R.H.'!A$3:C$3974,3,FALSE)*D27/100 -> #N/A | H27: =F27/D27 -> 0 | I27: =VLOOKUP(B27,'R.H.'!A$3:C$3974,3,FALSE)/100 -> #N/A | J27: 1 | K27: =E27/J27 -> #N/A | L27: 136 | N27: =K27/L27 -> #N/A | O27: =K27/(L27-M27) -> #N/A
A28: 24 | B28: 1830 | C28: =IF(ISBLANK(B28),"",VLOOKUP(B28,SÜRELER!$A:$B,2,FALSE)) -> #N/A | D28: 584 | E28: =IF(ISBLANK($B28),"0",VLOOKUP($B28,SÜRELER!$A:$C,3,FALSE))*(D28-F28) -> #N/A | F28: 10 | G28: =VLOOKUP(B28,'R.H.'!A$3:C$3974,3,FALSE)*D28/100 -> #N/A | H28: =F28/D28 -> 0.017123288 | I28: =VLOOKUP(B28,'R.H.'!A$3:C$3974,3,FALSE)/100 -> #N/A | J28: 1 | K28: =E28/J28 -> #N/A | L28: 148 | N28: =K28/L28 -> #N/A | O28: =K28/(L28-M28) -> #N/A
A29: 25 | C29: =IF(ISBLANK(B29),"",VLOOKUP(B29,SÜRELER!$A:$B,2,FALSE)) | E29: =IF(ISBLANK($B29),"0",VLOOKUP($B29,SÜRELER!$A:$C,3,FALSE))*(D29-F29) -> 0 | G29: =VLOOKUP(B29,'R.H.'!A$3:C$3974,3,FALSE)*D29/100 -> #N/A | H29: =F29/D29 -> #DIV/0! | I29: =VLOOKUP(B29,'R.H.'!A$3:C$3974,3,FALSE)/100 -> #N/A | K29: =E29/J29 -> #DIV/0! | N29: =K29/L29 -> #DIV/0! | O29: =K29/(L29-M29) -> #DIV/0!
A30: 26 | C30: =IF(ISBLANK(B30),"",VLOOKUP(B30,SÜRELER!$A:$B,2,FALSE)) | E30: =IF(ISBLANK($B30),"0",VLOOKUP($B30,SÜRELER!$A:$C,3,FALSE))*(D30-F30) -> 0 | G30: =VLOOKUP(B30,'R.H.'!A$3:C$3974,3,FALSE)*D30/100 -> #N/A | H30: =F30/D30 -> #DIV/0! | I30: =VLOOKUP(B30,'R.H.'!A$3:C$3974,3,FALSE)/100 -> #N/A | K30: =E30/J30 -> #DIV/0! | N30: =K30/L30 -> #DIV/0! | O30: =K30/(L30-M30) -> #DIV/0!
A31: 27 | C31: =IF(ISBLANK(B31),"",VLOOKUP(B31,SÜRELER!$A:$B,2,FALSE)) | E31: =IF(ISBLANK($B31),"0",VLOOKUP($B31,SÜRELER!$A:$C,3,FALSE))*(D31-F31) -> 0 | G31: =VLOOKUP(B31,'R.H.'!A$3:C$3974,3,FALSE)*D31/100 -> #N/A | H31: =F31/D31 -> #DIV/0! | I31: =VLOOKUP(B31,'R.H.'!A$3:C$3974,3,FALSE)/100 -> #N/A | K31: =E31/J31 -> #DIV/0! | N31: =K31/L31 -> #DIV/0! | O31: =K31/(L31-M31) -> #DIV/0!
A32: 28 | C32: =IF(ISBLANK(B32),"",VLOOKUP(B32,SÜRELER!$A:$B,2,FALSE)) | E32: =IF(ISBLANK($B32),"0",VLOOKUP($B32,SÜRELER!$A:$C,3,FALSE))*(D32-F32) -> 0 | G32: =VLOOKUP(B32,'R.H.'!A$3:C$3974,3,FALSE)*D32/100 -> #N/A | H32: =F32/D32 -> #DIV/0! | I32: =VLOOKUP(B32,'R.H.'!A$3:C$3974,3,FALSE)/100 -> #N/A | K32: =E32/J32 -> #DIV/0! | N32: =K32/L32 -> #DIV/0! | O32: =K32/(L32-M32) -> #DIV/0!
A33: 29 | C33: =IF(ISBLANK(B33),"",VLOOKUP(B33,SÜRELER!$A:$B,2,FALSE)) | E33: =IF(ISBLANK($B33),"0",VLOOKUP($B33,SÜRELER!$A:$C,3,FALSE))*(D33-F33) -> 0 | G33: =VLOOKUP(B33,'R.H.'!A$3:C$3974,3,FALSE)*D33/100 -> #N/A | H33: =F33/D33 -> #DIV/0! | I33: =VLOOKUP(B33,'R.H.'!A$3:C$3974,3,FALSE)/100 -> #N/A | K33: =E33/J33 -> #DIV/0! | N33: =K33/L33 -> #DIV/0! | O33: =K33/(L33-M33) -> #DIV/0!
A34: 30 | C34: =IF(ISBLANK(B34),"",VLOOKUP(B34,SÜRELER!$A:$B,2,FALSE)) | E34: =IF(ISBLANK($B34),"0",VLOOKUP($B34,SÜRELER!$A:$C,3,FALSE))*(D34-F34) -> 0 | G34: =VLOOKUP(B34,'R.H.'!A$3:C$3974,3,FALSE)*D34/100 -> #N/A | H34: =F34/D34 -> #DIV/0! | I34: =VLOOKUP(B34,'R.H.'!A$3:C$3974,3,FALSE)/100 -> #N/A | K34: =E34/J34 -> #DIV/0! | N34: =K34/L34 -> #DIV/0! | O34: =K34/(L34-M34) -> #DIV/0!
A35: 31 | C35: =IF(ISBLANK(B35),"",VLOOKUP(B35,SÜRELER!$A:$B,2,FALSE)) | E35: =IF(ISBLANK($B35),"0",VLOOKUP($B35,SÜRELER!$A:$C,3,FALSE))*(D35-F35) -> 0 | G35: =VLOOKUP(B35,'R.H.'!A$3:C$3974,3,FALSE)*D35/100 -> #N/A | H35: =F35/D35 -> #DIV/0! | I35: =VLOOKUP(B35,'R.H.'!A$3:C$3974,3,FALSE)/100 -> #N/A | K35: =E35/J35 -> #DIV/0! | N35: =K35/L35 -> #DIV/0! | O35: =K35/(L35-M35) -> #DIV/0!
A36: 32 | C36: =IF(ISBLANK(B36),"",VLOOKUP(B36,SÜRELER!$A:$B,2,FALSE)) | E36: =IF(ISBLANK($B36),"0",VLOOKUP($B36,SÜRELER!$A:$C,3,FALSE))*(D36-F36) -> 0 | G36: =VLOOKUP(B36,'R.H.'!A$3:C$3974,3,FALSE)*D36/100 -> #N/A | H36: =F36/D36 -> #DIV/0! | I36: =VLOOKUP(B36,'R.H.'!A$3:C$3974,3,FALSE)/100 -> #N/A | K36: =E36/J36 -> #DIV/0! | N36: =K36/L36 -> #DIV/0! | O36: =K36/(L36-M36) -> #DIV/0!
A37: 33 | C37: =IF(ISBLANK(B37),"",VLOOKUP(B37,SÜRELER!$A:$B,2,FALSE)) | E37: =IF(ISBLANK($B37),"0",VLOOKUP($B37,SÜRELER!$A:$C,3,FALSE))*(D37-F37) -> 0 | G37: =VLOOKUP(B37,'R.H.'!A$3:C$3974,3,FALSE)*D37/100 -> #N/A | H37: =F37/D37 -> #DIV/0! | I37: =VLOOKUP(B37,'R.H.'!A$3:C$3974,3,FALSE)/100 -> #N/A | K37: =E37/J37 -> #DIV/0! | N37: =K37/L37 -> #DIV/0! | O37: =K37/(L37-M37) -> #DIV/0!
A38: 34 | C38: =IF(ISBLANK(B38),"",VLOOKUP(B38,SÜRELER!$A:$B,2,FALSE)) | E38: =IF(ISBLANK($B38),"0",VLOOKUP($B38,SÜRELER!$A:$C,3,FALSE))*(D38-F38) -> 0 | G38: =VLOOKUP(B38,'R.H.'!A$3:C$3974,3,FALSE)*D38/100 -> #N/A | H38: =F38/D38 -> #DIV/0! | I38: =VLOOKUP(B38,'R.H.'!A$3:C$3974,3,FALSE)/100 -> #N/A | K38: =E38/J38 -> #DIV/0! | N38: =K38/L38 -> #DIV/0! | O38: =K38/(L38-M38) -> #DIV/0!
A39: 35 | C39: =IF(ISBLANK(B39),"",VLOOKUP(B39,SÜRELER!$A:$B,2,FALSE)) | E39: =IF(ISBLANK($B39),"0",VLOOKUP($B39,SÜRELER!$A:$C,3,FALSE))*(D39-F39) -> 0 | G39: =VLOOKUP(B39,'R.H.'!A$3:C$3974,3,FALSE)*D39/100 -> #N/A | H39: =F39/D39 -> #DIV/0! | I39: =VLOOKUP(B39,'R.H.'!A$3:C$3974,3,FALSE)/100 -> #N/A | K39: =E39/J39 -> #DIV/0! | N39: =K39/L39 -> #DIV/0! | O39: =K39/(L39-M39) -> #DIV/0!
A40: 36 | C40: =IF(ISBLANK(B40),"",VLOOKUP(B40,SÜRELER!$A:$B,2,FALSE)) | E40: =IF(ISBLANK($B40),"0",VLOOKUP($B40,SÜRELER!$A:$C,3,FALSE))*(D40-F40) -> 0 | G40: =VLOOKUP(B40,'R.H.'!A$3:C$3974,3,FALSE)*D40/100 -> #N/A | H40: =F40/D40 -> #DIV/0! | I40: =VLOOKUP(B40,'R.H.'!A$3:C$3974,3,FALSE)/100 -> #N/A | K40: =E40/J40 -> #DIV/0! | N40: =K40/L40 -> #DIV/0! | O40: =K40/(L40-M40) -> #DIV/0!
...

Sheet 3
A1: ='2'!A1+1 -> 46206 | H1: Genel Verimlilik | N1: =E45/D51 -> #N/A | P1: ANA SAYFA
A2: =TEXT(A1,"gggg") -> Cuma
C3: TOPLAM ÜRETİM | D3: =D45 -> 31629
A4: S.No | B4: P. Kod | C4: Ürün Tanımı | D4: Ürt. Adt | E4: Std. Süre Dk | G4: SAP Rjm Fire Adt | H4: Fire % | I4: SAP Std Fire % | K4: Std T.Süresi (Dk) | L4: Gerçekleşen Toplam Süre | M4: Kayıp Zamanlar Toplamı | N4: Ürün Performansı | O4: İşçilik Performansı | P4: Açıklama
A5: 1 | B5: 2076 | C5: =IF(ISBLANK(B5),"",VLOOKUP(B5,SÜRELER!$A:$B,2,FALSE)) -> #N/A | D5: 646 | E5: =IF(ISBLANK($B5),"0",VLOOKUP($B5,SÜRELER!$A:$C,3,FALSE))*(D5-F5) -> #N/A | F5: 6 | G5: =VLOOKUP(B5,'R.H.'!A$3:C$3974,3,FALSE)*D5/100 -> #N/A | H5: =F5/D5 -> 0.0092879257 | I5: =VLOOKUP(B5,'R.H.'!A$3:C$3974,3,FALSE)/100 -> #N/A | J5: 1 | K5: =E5/J5 -> #N/A | L5: 380 | N5: =K5/L5 -> #N/A | O5: =K5/(L5-M5) -> #N/A | P5: ENGEL 1700 YAG ARZASI 2K BEZEL İTİCİ SARMASI NEDENİYLE
A6: 2 | B6: 311 | C6: =IF(ISBLANK(B6),"",VLOOKUP(B6,SÜRELER!$A:$B,2,FALSE)) -> #N/A | D6: 108 | E6: =IF(ISBLANK($B6),"0",VLOOKUP($B6,SÜRELER!$A:$C,3,FALSE))*(D6-F6) -> #N/A | F6: 0 | G6: =VLOOKUP(B6,'R.H.'!A$3:C$3974,3,FALSE)*D6/100 -> #N/A | H6: =F6/D6 -> 0 | I6: =VLOOKUP(B6,'R.H.'!A$3:C$3974,3,FALSE)/100 -> #N/A | J6: 1 | K6: =E6/J6 -> #N/A | L6: 80 | N6: =K6/L6 -> #N/A | O6: =K6/(L6-M6) -> #N/A
A7: 3 | B7: 683 | C7: =IF(ISBLANK(B7),"",VLOOKUP(B7,SÜRELER!$A:$B,2,FALSE)) -> #N/A | D7: 455 | E7: =IF(ISBLANK($B7),"0",VLOOKUP($B7,SÜRELER!$A:$C,3,FALSE))*(D7-F7) -> #N/A | F7: 10 | G7: =VLOOKUP(B7,'R.H.'!A$3:C$3974,3,FALSE)*D7/100 -> #N/A | H7: =F7/D7 -> 0.021978022 | I7: =VLOOKUP(B7,'R.H.'!A$3:C$3974,3,FALSE)/100 -> #N/A | J7: 1 | K7: =E7/J7 -> #N/A | L7: 850 | N7: =K7/L7 -> #N/A | O7: =K7/(L7-M7) -> #N/A | P7: H625 ÇERÇEVE TEK ÜRETİM
A8: 4 | B8: 1934 | C8: =IF(ISBLANK(B8),"",VLOOKUP(B8,SÜRELER!$A:$B,2,FALSE)) -> #N/A | D8: 330 | E8: =IF(ISBLANK($B8),"0",VLOOKUP($B8,SÜRELER!$A:$C,3,FALSE))*(D8-F8) -> #N/A | F8: 5 | G8: =VLOOKUP(B8,'R.H.'!A$3:C$3974,3,FALSE)*D8/100 -> #N/A | H8: =F8/D8 -> 0.015151515 | I8: =VLOOKUP(B8,'R.H.'!A$3:C$3974,3,FALSE)/100 -> #N/A | J8: 0.5 | K8: =E8/J8 -> #N/A | L8: 3290 | N8: =K8/L8 -> #N/A | O8: =K8/(L8-M8) -> #N/A
A9: 5 | B9: 1935 | C9: =IF(ISBLANK(B9),"",VLOOKUP(B9,SÜRELER!$A:$B,2,FALSE)) -> #N/A | D9: 330 | E9: =IF(ISBLANK($B9),"0",VLOOKUP($B9,SÜRELER!$A:$C,3,FALSE))*(D9-F9) -> #N/A | F9: 5 | G9: =VLOOKUP(B9,'R.H.'!A$3:C$3974,3,FALSE)*D9/100 -> #N/A | H9: =F9/D9 -> 0.015151515 | I9: =VLOOKUP(B9,'R.H.'!A$3:C$3974,3,FALSE)/100 -> #N/A | J9: 0.5 | K9: =E9/J9 -> #N/A | L9: 3290 | N9: =K9/L9 -> #N/A | O9: =K9/(L9-M9) -> #N/A
A10: 6 | B10: 95 | C10: =IF(ISBLANK(B10),"",VLOOKUP(B10,SÜRELER!$A:$B,2,FALSE)) -> #N/A | D10: =290+119+149 -> 558 | E10: =IF(ISBLANK($B10),"0",VLOOKUP($B10,SÜRELER!$A:$C,3,FALSE))*(D10-F10) -> #N/A | F10: 66 | G10: =VLOOKUP(B10,'R.H.'!A$3:C$3974,3,FALSE)*D10/100 -> #N/A | H10: =F10/D10 -> 0.11827957 | I10: =VLOOKUP(B10,'R.H.'!A$3:C$3974,3,FALSE)/100 -> #N/A | J10: 1 | K10: =E10/J10 -> #N/A | L10: 600 | N10: =K10/L10 -> #N/A | O10: =K10/(L10-M10) -> #N/A | P10: H625 SİYAH ÇERÇEVE TIRNAK KIRILMASI
A11: 7 | B11: 81 | C11: =IF(ISBLANK(B11),"",VLOOKUP(B11,SÜRELER!$A:$B,2,FALSE)) -> #N/A | D11: =318+346 -> 664 | E11: =IF(ISBLANK($B11),"0",VLOOKUP($B11,SÜRELER!$A:$C,3,FALSE))*(D11-F11) -> #N/A | F11: 18 | G11: =VLOOKUP(B11,'R.H.'!A$3:C$3974,3,FALSE)*D11/100 -> #N/A | H11: =F11/D11 -> 0.027108434 | I11: =VLOOKUP(B11,'R.H.'!A$3:C$3974,3,FALSE)/100 -> #N/A | J11: 0.5 | K11: =E11/J11 -> #N/A | L11: 1085 | N11: =K11/L11 -> #N/A | O11: =K11/(L11-M11) -> #N/A
A12: 8 | B12: 82 | C12: =IF(ISBLANK(B12),"",VLOOKUP(B12,SÜRELER!$A:$B,2,FALSE)) -> #N/A | D12: 664 | E12: =IF(ISBLANK($B12),"0",VLOOKUP($B12,SÜRELER!$A:$C,3,FALSE))*(D12-F12) -> #N/A | F12: 18 | G12: =VLOOKUP(B12,'R.H.'!A$3:C$3974,3,FALSE)*D12/100 -> #N/A | H12: =F12/D12 -> 0.027108434 | I12: =VLOOKUP(B12,'R.H.'!A$3:C$3974,3,FALSE)/100 -> #N/A | J12: 0.5 | K12: =E12/J12 -> #N/A | L12: 1085 | N12: =K12/L12 -> #N/A | O12: =K12/(L12-M12) -> #N/A
A13: 9 | B13: 880 | C13: =IF(ISBLANK(B13),"",VLOOKUP(B13,SÜRELER!$A:$B,2,FALSE)) -> #N/A | D13: =231+126+110 -> 467 | E13: =IF(ISBLANK($B13),"0",VLOOKUP($B13,SÜRELER!$A:$C,3,FALSE))*(D13-F13) -> #N/A | F13: 25 | G13: =VLOOKUP(B13,'R.H.'!A$3:C$3974,3,FALSE)*D13/100 -> #N/A | H13: =F13/D13 -> 0.053533191 | I13: =VLOOKUP(B13,'R.H.'!A$3:C$3974,3,FALSE)/100 -> #N/A | J13: 0.5 | K13: =E13/J13 -> #N/A | L13: 335 | N13: =K13/L13 -> #N/A | O13: =K13/(L13-M13) -> #N/A
A14: 10 | B14: 881 | C14: =IF(ISBLANK(B14),"",VLOOKUP(B14,SÜRELER!$A:$B,2,FALSE)) -> #N/A | D14: =236+231 -> 467 | E14: =IF(ISBLANK($B14),"0",VLOOKUP($B14,SÜRELER!$A:$C,3,FALSE))*(D14-F14) -> #N/A | F14: 25 | G14: =VLOOKUP(B14,'R.H.'!A$3:C$3974,3,FALSE)*D14/100 -> #N/A | H14: =F14/D14 -> 0.053533191 | I14: =VLOOKUP(B14,'R.H.'!A$3:C$3974,3,FALSE)/100 -> #N/A | J14: 0.5 | K14: =E14/J14 -> #N/A | L14: 335 | N14: =K14/L14 -> #N/A | O14: =K14/(L14-M14) -> #N/A
A15: 11 | B15: 1591 | C15: =IF(ISBLANK(B15),"",VLOOKUP(B15,SÜRELER!$A:$B,2,FALSE)) -> #N/A | D15: =318+412 -> 730 | E15: =IF(ISBLANK($B15),"0",VLOOKUP($B15,SÜRELER!$A:$C,3,FALSE))*(D15-F15) -> #N/A | F15: 0 | G15: =VLOOKUP(B15,'R.H.'!A$3:C$3974,3,FALSE)*D15/100 -> #N/A | H15: =F15/D15 -> 0 | I15: =VLOOKUP(B15,'R.H.'!A$3:C$3974,3,FALSE)/100 -> #N/A | J15: 0.5 | K15: =E15/J15 -> #N/A | L15: 550 | N15: =K15/L15 -> #N/A | O15: =K15/(L15-M15) -> #N/A
A16: 12 | B16: 1592 | C16: =IF(ISBLANK(B16),"",VLOOKUP(B16,SÜRELER!$A:$B,2,FALSE)) -> #N/A | D16: 730 | E16: =IF(ISBLANK($B16),"0",VLOOKUP($B16,SÜRELER!$A:$C,3,FALSE))*(D16-F16) -> #N/A | F16: 0 | G16: =VLOOKUP(B16,'R.H.'!A$3:C$3974,3,FALSE)*D16/100 -> #N/A | H16: =F16/D16 -> 0 | I16: =VLOOKUP(B16,'R.H.'!A$3:C$3974,3,FALSE)/100 -> #N/A | J16: 0.5 | K16: =E16/J16 -> #N/A | L16: 550 | N16: =K16/L16 -> #N/A | O16: =K16/(L16-M16) -> #N/A
